Workbook

Sheet Forward EPS
A1: 표 1. ISC 실적 추이 및 전망 | B1: 표 1. ISC 실적 추이 및 전망 | C1: 표 1. ISC 실적 추이 및 전망 | D1: 표 1. ISC 실적 추이 및 전망 | E1: 표 1. ISC 실적 추이 및 전망 | F1: 표 1. ISC 실적 추이 및 전망 | G1: 표 1. ISC 실적 추이 및 전망 | H1: 표 1. ISC 실적 추이 및 전망 | I1: 표 1. ISC 실적 추이 및 전망 | J1: 표 1. ISC 실적 추이 및 전망 | K1: 표 1. ISC 실적 추이 및 전망 | L1: 표 1. ISC 실적 추이 및 전망
A2: 표 1. ISC 실적 추이 및 전망 | B2: 표 1. ISC 실적 추이 및 전망 | C2: 표 1. ISC 실적 추이 및 전망 | D2: 표 1. ISC 실적 추이 및 전망 | E2: 표 1. ISC 실적 추이 및 전망 | F2: 표 1. ISC 실적 추이 및 전망 | G2: 표 1. ISC 실적 추이 및 전망 | H2: 표 1. ISC 실적 추이 및 전망 | I2: 표 1. ISC 실적 추이 및 전망 | J2: 표 1. ISC 실적 추이 및 전망 | K2: 표 1. ISC 실적 추이 및 전망 | L2: 표 1. ISC 실적 추이 및 전망
A3: ISC (095340) | 리서치 기준일 2026-04-28 | 단위는 각 표에 표시 | 삼성증권 1Q26 Review 및 사용자 제공 ZIP 기반
A4: 입력/추정 가정: 연노랑 배경 + 파란 글씨 | 계산식: 검은 글씨 | 다른 시트 연결: 초록 글씨
A5: 항목 | B5: 1Q25 | C5: 2Q25 | D5: 3Q25 | E5: 4Q25 | F5: 1Q26P | G5: 2Q26E | H5: 3Q26E | I5: 4Q26E | J5: 2025 | K5: 2026E | L5: 2027E
A6: 매출액 | B6: 31.7 | C6: 51.7 | D6: 64.5 | E6: 72.3 | F6: 68.3 | G6: 72.7 | H6: 84.3 | I6: 88.9 | J6: 220.2 | K6: 314.2 | L6: 402.5
A7: 데이터센터 | B7: 16.9 | C7: 33.1 | D7: 44 | E7: 54.4 | F7: 54.2 | G7: 57.5 | H7: 68.2 | I7: 75.2 | J7: 148.4 | K7: 255 | L7: 336.1
A8: 스마트폰 | B8: 9.5 | C8: 14 | D8: 13.5 | E8: 12 | F8: 11 | G8: 11.6 | H8: 11 | I8: 8.8 | J8: 49 | K8: 42.3 | L8: 46.2
A9: PC/노트북 | B9: 3.2 | C9: 3 | D9: 4.5 | E9: 3 | F9: 1.6 | G9: 1.6 | H9: 2.2 | I9: 1.7 | J9: 13.7 | K9: 7.1 | L9: 7.7
A10: 자동차 | B10: 1 | C10: 0.7 | D10: 1.5 | E10: 1.9 | F10: 1.5 | G10: 1.1 | H10: 1.8 | I10: 1.9 | J10: 5.1 | K10: 6.3 | L10: 6.7
A11: 웨어러블 | B11: 0.7 | C11: 0.7 | D11: 0.8 | E11: 1 | F11: 0 | G11: 1.1 | H11: 1.2 | I11: 1.4 | J11: 3.2 | K11: 3.6 | L11: 5.9
A12: LSI | B12: 0 | C12: 0 | D12: 0 | E12: 0 | F12: 0 | G12: 0 | H12: 0 | I12: 0 | J12: 0 | K12: 0 | L12: 0
A13: Non-Socket | B13: 0.4 | C13: 0.2 | D13: 0.2 | E13: 0 | F13: 0 | G13: 0 | H13: 0 | I13: 0 | J13: 0.8 | K13: 0 | L13: 0
A14: 매출액 YoY | B14: -9.7 | C14: 3.8 | D14: 28 | E14: 84.3 | F14: 115.5 | G14: 40.7 | H14: 30.7 | I14: 23 | J14: 26.2 | K14: 42.7 | L14: 28.1
A15: 매출액 QoQ | B15: -19.3 | C15: 63 | D15: 24.9 | E15: 12.1 | F15: -5.6 | G15: 6.5 | H15: 16 | I15: 5.5
A16: 매출원가 | B16: 17.4 | C16: 29.1 | D16: 36.9 | E16: 39 | F16: 32.9 | G16: 39.3 | H16: 46.2 | I16: 47.8 | J16: 122.5 | K16: 166.2 | L16: 211.9
A17: 매출총이익 | B17: 14.2 | C17: 22.5 | D17: 27.6 | E17: 33.3 | F17: 35.4 | G17: 33.4 | H17: 38.1 | I17: 41.2 | J17: 97.7 | K17: 148.1 | L17: 190.6
A18: 매출총이익률 | B18: 44.9 | C18: 43.6 | D18: 42.8 | E18: 46.1 | F18: 51.9 | G18: 45.9 | H18: 45.2 | I18: 46.3 | J18: 44.4 | K18: 47.1 | L18: 47.4
A19: 판매 및 일반관리비 | B19: 7.2 | C19: 8.8 | D19: 10.2 | E19: 11.4 | F19: 11.8 | G19: 10.6 | H19: 11.8 | I19: 13.5 | J19: 37.7 | K19: 47.6 | L19: 53.8
A20: 영업이익 | B20: 7 | C20: 13.7 | D20: 17.4 | E20: 21.9 | F20: 23.6 | G20: 22.8 | H20: 26.4 | I20: 27.7 | J20: 60.1 | K20: 100.4 | L20: 136.8
A21: 영업이익률 | B21: 22.1 | C21: 26.5 | D21: 27 | E21: 30.3 | F21: 34.6 | G21: 31.4 | H21: 31.3 | I21: 31.1 | J21: 27.3 | K21: 32 | L21: 34
A22: 세전이익 | B22: 9.3 | C22: 13.5 | D22: 19.8 | E22: 24 | F22: 26.6 | G22: 25.9 | H22: 29.5 | I22: 30.7 | J22: 66.6 | K22: 112.6 | L22: 148.1
A23: 지배주주순이익 | B23: 6.8 | C23: 11.5 | D23: 16.1 | E23: 21.7 | F23: 20.5 | G23: 20.1 | H23: 22.9 | I23: 23.8 | J23: 56.1 | K23: 87.3 | L23: 115.1
A24: 지배주주순이익률 | B24: 21.6 | C24: 22.3 | D24: 24.9 | E24: 30 | F24: 30 | G24: 27.7 | H24: 27.1 | I24: 26.8 | J24: 25.5 | K24: 27.8 | L24: 28.6
A25: EPS (원) | B25: 334 | C25: 562 | D25: 785 | E25: 1062 | F25: 1000 | G25: 983 | H25: 1118 | I25: 1164 | J25: 2743 | K25: 4266 | L25: 5623
A26: EPS YoY | B26: -56.7 | C26: -28 | D26: 44.4 | E26: 84.4 | F26: 199.6 | G26: 74.9 | H26: 42.4 | I26: 9.7 | J26: 2.7 | K26: 55.5 | L26: 31.8
A27: EPS QoQ | B27: -42 | C27: 68.3 | D27: 39.8 | E27: 35.2 | F27: -5.8 | G27: -1.7 | H27: 13.8 | I27: 4.1
A29: 자료: ISC, 삼성증권 2026-04-28 p.2 | 금액 단위: 십억원, 비율 단위: %

Sheet Target PER
A1: Target PER 선정 및 목표주가 모델 | B1: Target PER 선정 및 목표주가 모델 | C1: Target PER 선정 및 목표주가 모델 | D1: Target PER 선정 및 목표주가 모델 | E1: Target PER 선정 및 목표주가 모델 | F1: Target PER 선정 및 목표주가 모델 | G1: Target PER 선정 및 목표주가 모델 | H1: Target PER 선정 및 목표주가 모델 | I1: Target PER 선정 및 목표주가 모델
A2: Target PER 선정 및 목표주가 모델 | B2: Target PER 선정 및 목표주가 모델 | C2: Target PER 선정 및 목표주가 모델 | D2: Target PER 선정 및 목표주가 모델 | E2: Target PER 선정 및 목표주가 모델 | F2: Target PER 선정 및 목표주가 모델 | G2: Target PER 선정 및 목표주가 모델 | H2: Target PER 선정 및 목표주가 모델 | I2: Target PER 선정 및 목표주가 모델
A3: ISC (095340) | 리서치 기준일 2026-04-28 | 단위는 각 표에 표시 | 삼성증권 1Q26 Review 및 사용자 제공 ZIP 기반
A4: 입력/추정 가정: 연노랑 배경 + 파란 글씨 | 계산식: 검은 글씨 | 다른 시트 연결: 초록 글씨
A5: Target PER 선택 로직 | B5: Target PER 선택 로직 | C5: Target PER 선택 로직 | D5: Target PER 선택 로직 | E5: Target PER 선택 로직 | F5: Target PER 선택 로직 | G5: Target PER 선택 로직 | H5: Target PER 선택 로직 | I5: Target PER 선택 로직
A6: 선정 방식 | B6: 특정 피어 조정 | D6: 현재 선택: WinWay 88.92배에서 40% 할인 → Target P/E 53.35배
A7: Forward EPS | B7: ='08_Forward_EPS'!D36 -> 5618.4737 | D7: Forward EPS는 08_Forward_EPS의 FY27E EPS와 직접 연결됩니다.
A8: 선택 피어 | B8: WinWay | D8: 선정 방식을 바꾸면 국내 피어 평균·중앙값 또는 직접 입력값이 즉시 반영됩니다.
A9: 선택 피어 P/E | B9: =INDEX(C22:C26,MATCH(B8,A22:A26,0)) -> 88.920505 | D9: 특정 피어의 시장 P/E가 갱신되면 B9와 할인/프리미엄 B10을 함께 검토하십시오.
A10: 할인/프리미엄 | B10: -0.4
A11: 피어 평균 P/E | B11: =AVERAGE(F22:F26) -> 26.44
A12: 피어 중앙값 P/E | B12: =MEDIAN(F22:F26) -> 25.385
A13: 직접 입력 P/E | B13: 53.352303
A14: 도출 Target P/E | B14: =IF(B6="특정 피어 조정",B9*(1+B10),IF(B6="피어 평균",B11,IF(B6="피어 중앙값",B12,B13))) -> 53.352303
A15: 목표주가 (원) | B15: =ROUND(B7*B14,-3) -> 300000
A16: 현재주가 (원) | B16: 240500
A17: 상승여력 | B17: =B15/B16-1 -> 0.24740125
A20: 피어 정보 및 참고 멀티플 | B20: 피어 정보 및 참고 멀티플 | C20: 피어 정보 및 참고 멀티플 | D20: 피어 정보 및 참고 멀티플 | E20: 피어 정보 및 참고 멀티플 | F20: 피어 정보 및 참고 멀티플 | G20: 피어 정보 및 참고 멀티플 | H20: 피어 정보 및 참고 멀티플 | I20: 피어 정보 및 참고 멀티플
A21: 기업명 | B21: 시장 | C21: 기준 P/E | D21: Include | E21: 조정률 | F21: 적용 P/E
A22: WinWay | B22: TWSE | C22: 88.920505 | D22: N | E22: -0.4 | F22: =IF(D22="Y",C22*(1+E22),"")
A23: 리노공업 | B23: KOSDAQ | C23: 28.3 | D23: Y | E23: 0 | F23: =IF(D23="Y",C23*(1+E23),"") -> 28.3
A24: 티에스이 | B24: KOSDAQ | C24: 22.47 | D24: Y | E24: 0 | F24: =IF(D24="Y",C24*(1+E24),"") -> 22.47
A25: 테크윙 | B25: KOSDAQ | C25: 15.68 | D25: Y | E25: 0 | F25: =IF(D25="Y",C25*(1+E25),"") -> 15.68
A26: 두산테스나 | B26: KOSDAQ | C26: 39.31 | D26: Y | E26: 0 | F26: =IF(D26="Y",C26*(1+E26),"") -> 39.31
A28: 피어 평균 P/E | F28: =AVERAGE(F22:F26) -> 26.44
A29: 피어 중앙값 P/E | F29: =MEDIAN(F22:F26) -> 25.385

Sheet 00_요약
A1: ISC 1Q26 Review & WinWay Peer PER Valuation 모델 | B1: ISC 1Q26 Review & WinWay Peer PER Valuation 모델 | C1: ISC 1Q26 Review & WinWay Peer PER Valuation 모델 | D1: ISC 1Q26 Review & WinWay Peer PER Valuation 모델 | E1: ISC 1Q26 Review & WinWay Peer PER Valuation 모델 | F1: ISC 1Q26 Review & WinWay Peer PER Valuation 모델 | G1: ISC 1Q26 Review & WinWay Peer PER Valuation 모델 | H1: ISC 1Q26 Review & WinWay Peer PER Valuation 모델
A2: ISC 1Q26 Review & WinWay Peer PER Valuation 모델 | B2: ISC 1Q26 Review & WinWay Peer PER Valuation 모델 | C2: ISC 1Q26 Review & WinWay Peer PER Valuation 모델 | D2: ISC 1Q26 Review & WinWay Peer PER Valuation 모델 | E2: ISC 1Q26 Review & WinWay Peer PER Valuation 모델 | F2: ISC 1Q26 Review & WinWay Peer PER Valuation 모델 | G2: ISC 1Q26 Review & WinWay Peer PER Valuation 모델 | H2: ISC 1Q26 Review & WinWay Peer PER Valuation 모델
A3: ISC (095340) | 리서치 기준일 2026-04-28 | 단위는 각 표에 표시 | 삼성증권 1Q26 Review 및 사용자 제공 ZIP 기반
A4: 입력/추정 가정: 연노랑 배경 + 파란 글씨 | 계산식: 검은 글씨 | 다른 시트 연결: 초록 글씨
A5: 핵심 투자지표 | B5: 핵심 투자지표 | C5: 핵심 투자지표 | D5: 핵심 투자지표 | E5: 핵심 투자지표 | F5: 핵심 투자지표 | G5: 핵심 투자지표 | H5: 핵심 투자지표
A6: 투자의견 | B6: BUY | D6: FY26E 매출액 (십억원) | E6: 314.2
A7: 목표주가 (원) | B7: ='03_목표주가'!B11 -> 300000 | D7: FY26E 영업이익 (십억원) | E7: 100.4934
A8: 현재주가 (원) | B8: ='03_목표주가'!B12 -> 240500 | D8: FY27E 매출액 (십억원) | E8: 402.5
A9: 상승여력 | B9: ='03_목표주가'!B13 -> 0.24740125 | D9: FY27E 영업이익 (십억원) | E9: 136.85
A10: 목표 P/E | B10: ='03_목표주가'!B9 -> 53.352303 | D10: FY27E EPS (원) | E10: 5626.2243
A11: 목표 EPS 기준 | B11: FY27E | D11: 피어 수 | E11: 4
A13: 핵심 내용 | B13: 핵심 내용 | C13: 핵심 내용 | D13: 핵심 내용 | E13: 핵심 내용 | F13: 핵심 내용 | G13: 핵심 내용 | H13: 핵심 내용
A14: • 1Q26 매출 683억원(YoY +115.5%), 영업이익 236억원(OPM 34.6%)으로 고수익 AI 매출 기여가 확대.
A15: • System Level Test(SLT) 비중 확대와 HBM·AI CPU 관련 매출 본격화가 수익성 개선의 핵심.
A16: • 패키지 모델은 2Q26 매출 727억원, 영업이익 228억원과 FY26 매출 3,142억원·영업이익 1,005억원을 반영.
A17: • FY27E 지배주주순이익 1,151억원과 희석주식수 20.46백만주로 EPS 5,626원을 산출.
A18: • 삼성증권 방식대로 WinWay 기준 P/E에서 40% 할인한 Target P/E 53.35배를 적용해 목표주가 300,000원을 산정.
A20: 워크북 사용 안내 | B20: 워크북 사용 안내 | C20: 워크북 사용 안내 | D20: 워크북 사용 안내 | E20: 워크북 사용 안내 | F20: 워크북 사용 안내 | G20: 워크북 사용 안내 | H20: 워크북 사용 안내
A21: 파란 글씨: 리서치·ZIP 원문 기반 입력 | 검은 글씨: 수식 | 초록 글씨: 다른 시트 참조
A22: 솔브레인 파일과 동일한 8개 시트 순서는 유지하되 삼성증권 ISC 보고서의 표 순서와 구성을 우선 반영했습니다.
A23: 목표주가는 WinWay P/E 40% 할인 방식을 사용하며 국내 KOSPI/KOSDAQ 피어 표는 보조 비교자료로 유지합니다.
A24: 보고서에 WinWay의 정확한 기준 P/E가 표시되지 않아 88.92배는 보고서 목표주가·FY27E EPS·40% 할인율로 역산한 값입니다.

Sheet 01_실적추이
A1: 표 1. ISC 실적 추이 및 전망 | B1: 표 1. ISC 실적 추이 및 전망 | C1: 표 1. ISC 실적 추이 및 전망 | D1: 표 1. ISC 실적 추이 및 전망 | E1: 표 1. ISC 실적 추이 및 전망 | F1: 표 1. ISC 실적 추이 및 전망 | G1: 표 1. ISC 실적 추이 및 전망 | H1: 표 1. ISC 실적 추이 및 전망 | I1: 표 1. ISC 실적 추이 및 전망 | J1: 표 1. ISC 실적 추이 및 전망 | K1: 표 1. ISC 실적 추이 및 전망 | L1: 표 1. ISC 실적 추이 및 전망
A2: 표 1. ISC 실적 추이 및 전망 | B2: 표 1. ISC 실적 추이 및 전망 | C2: 표 1. ISC 실적 추이 및 전망 | D2: 표 1. ISC 실적 추이 및 전망 | E2: 표 1. ISC 실적 추이 및 전망 | F2: 표 1. ISC 실적 추이 및 전망 | G2: 표 1. ISC 실적 추이 및 전망 | H2: 표 1. ISC 실적 추이 및 전망 | I2: 표 1. ISC 실적 추이 및 전망 | J2: 표 1. ISC 실적 추이 및 전망 | K2: 표 1. ISC 실적 추이 및 전망 | L2: 표 1. ISC 실적 추이 및 전망
A3: ISC (095340) | 리서치 기준일 2026-04-28 | 단위는 각 표에 표시 | 삼성증권 1Q26 Review 및 사용자 제공 ZIP 기반
A4: 입력/추정 가정: 연노랑 배경 + 파란 글씨 | 계산식: 검은 글씨 | 다른 시트 연결: 초록 글씨
A5: 항목 | B5: 1Q25 | C5: 2Q25 | D5: 3Q25 | E5: 4Q25 | F5: 1Q26P | G5: 2Q26E | H5: 3Q26E | I5: 4Q26E | J5: 2025 | K5: 2026E | L5: 2027E
A6: 매출액 | B6: 31.7 | C6: 51.7 | D6: 64.5 | E6: 72.3 | F6: 68.3 | G6: 72.7 | H6: 84.3 | I6: 88.9 | J6: 220.2 | K6: 314.2 | L6: 402.5
A7: 데이터센터 | B7: 16.9 | C7: 33.1 | D7: 44 | E7: 54.4 | F7: 54.2 | G7: 57.5 | H7: 68.2 | I7: 75.2 | J7: 148.4 | K7: 255 | L7: 336.1
A8: 스마트폰 | B8: 9.5 | C8: 14 | D8: 13.5 | E8: 12 | F8: 11 | G8: 11.6 | H8: 11 | I8: 8.8 | J8: 49 | K8: 42.3 | L8: 46.2
A9: PC/노트북 | B9: 3.2 | C9: 3 | D9: 4.5 | E9: 3 | F9: 1.6 | G9: 1.6 | H9: 2.2 | I9: 1.7 | J9: 13.7 | K9: 7.1 | L9: 7.7
A10: 자동차 | B10: 1 | C10: 0.7 | D10: 1.5 | E10: 1.9 | F10: 1.5 | G10: 1.1 | H10: 1.8 | I10: 1.9 | J10: 5.1 | K10: 6.3 | L10: 6.7
A11: 웨어러블 | B11: 0.7 | C11: 0.7 | D11: 0.8 | E11: 1 | F11: 0 | G11: 1.1 | H11: 1.2 | I11: 1.4 | J11: 3.2 | K11: 3.6 | L11: 5.9
A12: LSI | B12: 0 | C12: 0 | D12: 0 | E12: 0 | F12: 0 | G12: 0 | H12: 0 | I12: 0 | J12: 0 | K12: 0 | L12: 0
A13: Non-Socket | B13: 0.4 | C13: 0.2 | D13: 0.2 | E13: 0 | F13: 0 | G13: 0 | H13: 0 | I13: 0 | J13: 0.8 | K13: 0 | L13: 0
A14: 매출액 YoY | B14: -9.7 | C14: 3.8 | D14: 28 | E14: 84.3 | F14: 115.5 | G14: 40.7 | H14: 30.7 | I14: 23 | J14: 26.2 | K14: 42.7 | L14: 28.1
A15: 매출액 QoQ | B15: -19.3 | C15: 63 | D15: 24.9 | E15: 12.1 | F15: -5.6 | G15: 6.5 | H15: 16 | I15: 5.5
A16: 매출원가 | B16: 17.4 | C16: 29.1 | D16: 36.9 | E16: 39 | F16: 32.9 | G16: 39.3 | H16: 46.2 | I16: 47.8 | J16: 122.5 | K16: 166.2 | L16: 211.9
A17: 매출총이익 | B17: 14.2 | C17: 22.5 | D17: 27.6 | E17: 33.3 | F17: 35.4 | G17: 33.4 | H17: 38.1 | I17: 41.2 | J17: 97.7 | K17: 148.1 | L17: 190.6
A18: 매출총이익률 | B18: 44.9 | C18: 43.6 | D18: 42.8 | E18: 46.1 | F18: 51.9 | G18: 45.9 | H18: 45.2 | I18: 46.3 | J18: 44.4 | K18: 47.1 | L18: 47.4
A19: 판매 및 일반관리비 | B19: 7.2 | C19: 8.8 | D19: 10.2 | E19: 11.4 | F19: 11.8 | G19: 10.6 | H19: 11.8 | I19: 13.5 | J19: 37.7 | K19: 47.6 | L19: 53.8
A20: 영업이익 | B20: 7 | C20: 13.7 | D20: 17.4 | E20: 21.9 | F20: 23.6 | G20: 22.8 | H20: 26.4 | I20: 27.7 | J20: 60.1 | K20: 100.4 | L20: 136.8
A21: 영업이익률 | B21: 22.1 | C21: 26.5 | D21: 27 | E21: 30.3 | F21: 34.6 | G21: 31.4 | H21: 31.3 | I21: 31.1 | J21: 27.3 | K21: 32 | L21: 34
A22: 세전이익 | B22: 9.3 | C22: 13.5 | D22: 19.8 | E22: 24 | F22: 26.6 | G22: 25.9 | H22: 29.5 | I22: 30.7 | J22: 66.6 | K22: 112.6 | L22: 148.1
A23: 지배주주순이익 | B23: 6.8 | C23: 11.5 | D23: 16.1 | E23: 21.7 | F23: 20.5 | G23: 20.1 | H23: 22.9 | I23: 23.8 | J23: 56.1 | K23: 87.3 | L23: 115.1
A24: 지배주주순이익률 | B24: 21.6 | C24: 22.3 | D24: 24.9 | E24: 30 | F24: 30 | G24: 27.7 | H24: 27.1 | I24: 26.8 | J24: 25.5 | K24: 27.8 | L24: 28.6
A25: EPS (원) | B25: 334 | C25: 562 | D25: 785 | E25: 1062 | F25: 1000 | G25: 983 | H25: 1118 | I25: 1164 | J25: 2743 | K25: 4266 | L25: 5623
A26: EPS YoY | B26: -56.7 | C26: -28 | D26: 44.4 | E26: 84.4 | F26: 199.6 | G26: 74.9 | H26: 42.4 | I26: 9.7 | J26: 2.7 | K26: 55.5 | L26: 31.8
A27: EPS QoQ | B27: -42 | C27: 68.3 | D27: 39.8 | E27: 35.2 | F27: -5.8 | G27: -1.7 | H27: 13.8 | I27: 4.1
A29: 자료: ISC, 삼성증권 2026-04-28 p.2 | 금액 단위: 십억원, 비율 단위: %

Sheet 02_추정변경
A1: 표 2. 수익추정 및 목표주가 변경 | B1: 표 2. 수익추정 및 목표주가 변경 | C1: 표 2. 수익추정 및 목표주가 변경 | D1: 표 2. 수익추정 및 목표주가 변경 | E1: 표 2. 수익추정 및 목표주가 변경 | F1: 표 2. 수익추정 및 목표주가 변경 | G1: 표 2. 수익추정 및 목표주가 변경 | H1: 표 2. 수익추정 및 목표주가 변경 | I1: 표 2. 수익추정 및 목표주가 변경 | J1: 표 2. 수익추정 및 목표주가 변경 | K1: 표 2. 수익추정 및 목표주가 변경
A2: 표 2. 수익추정 및 목표주가 변경 | B2: 표 2. 수익추정 및 목표주가 변경 | C2: 표 2. 수익추정 및 목표주가 변경 | D2: 표 2. 수익추정 및 목표주가 변경 | E2: 표 2. 수익추정 및 목표주가 변경 | F2: 표 2. 수익추정 및 목표주가 변경 | G2: 표 2. 수익추정 및 목표주가 변경 | H2: 표 2. 수익추정 및 목표주가 변경 | I2: 표 2. 수익추정 및 목표주가 변경 | J2: 표 2. 수익추정 및 목표주가 변경 | K2: 표 2. 수익추정 및 목표주가 변경
A3: ISC (095340) | 리서치 기준일 2026-04-28 | 단위는 각 표에 표시 | 삼성증권 1Q26 Review 및 사용자 제공 ZIP 기반
A4: 입력/추정 가정: 연노랑 배경 + 파란 글씨 | 계산식: 검은 글씨 | 다른 시트 연결: 초록 글씨
A5: 항목 | B5: 현재 모델 FY26E | C5: 현재 모델 FY27E | D5: 이전 보고서 FY26E | E5: 이전 보고서 FY27E | F5: 변경률 FY26E | G5: 변경률 FY27E | H5: 삼성증권 항목 | I5: 신규 | J5: 기존 | K5: 증감
A6: 매출액 (십억원) | B6: 314.2 | C6: 402.5 | F6: =IFERROR(B6/D6-1,"N/A") -> N/A | G6: =IFERROR(C6/E6-1,"N/A") -> N/A | H6: 목표주가 | I6: 300000 | J6: 280000 | K6: =I6/J6-1 -> 0.071428571
A7: 영업이익 (십억원) | B7: 100.4934 | C7: 136.85 | F7: =IFERROR(B7/D7-1,"N/A") -> N/A | G7: =IFERROR(C7/E7-1,"N/A") -> N/A | H7: 2026E EPS | I7: 4266 | J7: 4109 | K7: =I7/J7-1 -> 0.03820881
A8: EPS (원) | B8: 4262.4228 | C8: 5626.2243 | D8: 4109 | E8: 5395 | F8: =B8/D8-1 -> 0.037338245 | G8: =C8/E8-1 -> 0.042859006 | H8: 2027E EPS | I8: 5623 | J8: 5395 | K8: =I8/J8-1 -> 0.042261353
A10: 이전 보고서 수치는 삼성증권 2026-04-28 p.1의 EPS 변경표에서 가져왔습니다. 매출액·영업이익의 이전 수치는 해당 표에 없어 빈칸으로 보존했습니다. 우측 삼성증권 증감은 신규 ÷ 기존 - 1 수식입니다.

Sheet 03_목표주가
A1: 표 3. 목표주가 산정 | B1: 표 3. 목표주가 산정 | C1: 표 3. 목표주가 산정 | D1: 표 3. 목표주가 산정 | E1: 표 3. 목표주가 산정 | F1: 표 3. 목표주가 산정
A2: 표 3. 목표주가 산정 | B2: 표 3. 목표주가 산정 | C2: 표 3. 목표주가 산정 | D2: 표 3. 목표주가 산정 | E2: 표 3. 목표주가 산정 | F2: 표 3. 목표주가 산정
A3: ISC (095340) | 리서치 기준일 2026-04-28 | 단위는 각 표에 표시 | 삼성증권 1Q26 Review 및 사용자 제공 ZIP 기반
A4: 입력/추정 가정: 연노랑 배경 + 파란 글씨 | 계산식: 검은 글씨 | 다른 시트 연결: 초록 글씨
A5: 항목 | B5: 값 | C5: 비고
A6: FY27E EPS | B6: 5623 | C6: 삼성증권 2026-04-28
A7: WinWay 기준 P/E | B7: 88.920505 | C7: 보고서 수치로 역산
A8: 할인율 | B8: 0.4 | C8: 삼성증권: WinWay 대비 40% 할인
A9: 적용 Target P/E | B9: =B7*(1-B8) -> 53.352303 | C9: WinWay P/E × (1-할인율)
A10: 산출 목표주가 | B10: =B6*B9 -> 300000 | C10: EPS × Target P/E
A11: 제시 목표주가 | B11: =ROUND(B10,-3) -> 300000 | C11: 1,000원 단위 반올림
A12: 현재주가 | B12: 240500 | C12: 2026-04-27, 보고서 기준
A13: 상승여력 | B13: =B11/B12-1 -> 0.24740125 | C13: 제시 목표주가 ÷ 현재주가 - 1
A16: WinWay 적용 근거 및 해석 | B16: WinWay 적용 근거 및 해석 | C16: WinWay 적용 근거 및 해석 | D16: WinWay 적용 근거 및 해석 | E16: WinWay 적용 근거 및 해석 | F16: WinWay 적용 근거 및 해석
A17: 본 모델: FY27E EPS 5,623원 × [WinWay P/E 88.92배 × (1-40%)] = 목표주가 300,000원
A18: 삼성증권 보고서는 'WinWay 대비 40% 할인'만 명시하고 기준 P/E 수치는 제시하지 않아, 88.92배는 목표주가에서 역산했습니다.
A19: 국내 상장 피어 4개사의 Forward P/E 중앙값 25.385배는 05_피어밸류에서 보조 비교지표로 유지하며 목표주가에는 사용하지 않습니다.
A20: WinWay 시장 P/E 또는 적용 EPS를 갱신할 때에는 B6:B8 입력과 목표주가·상승여력·검증 체크를 함께 확인하십시오.

Sheet 04_피어실적
A1: 표 4. 국내 반도체 테스트 인터페이스 피어 실적·사업 비교 | B1: 표 4. 국내 반도체 테스트 인터페이스 피어 실적·사업 비교 | C1: 표 4. 국내 반도체 테스트 인터페이스 피어 실적·사업 비교 | D1: 표 4. 국내 반도체 테스트 인터페이스 피어 실적·사업 비교 | E1: 표 4. 국내 반도체 테스트 인터페이스 피어 실적·사업 비교 | F1: 표 4. 국내 반도체 테스트 인터페이스 피어 실적·사업 비교 | G1: 표 4. 국내 반도체 테스트 인터페이스 피어 실적·사업 비교 | H1: 표 4. 국내 반도체 테스트 인터페이스 피어 실적·사업 비교 | I1: 표 4. 국내 반도체 테스트 인터페이스 피어 실적·사업 비교
A2: 표 4. 국내 반도체 테스트 인터페이스 피어 실적·사업 비교 | B2: 표 4. 국내 반도체 테스트 인터페이스 피어 실적·사업 비교 | C2: 표 4. 국내 반도체 테스트 인터페이스 피어 실적·사업 비교 | D2: 표 4. 국내 반도체 테스트 인터페이스 피어 실적·사업 비교 | E2: 표 4. 국내 반도체 테스트 인터페이스 피어 실적·사업 비교 | F2: 표 4. 국내 반도체 테스트 인터페이스 피어 실적·사업 비교 | G2: 표 4. 국내 반도체 테스트 인터페이스 피어 실적·사업 비교 | H2: 표 4. 국내 반도체 테스트 인터페이스 피어 실적·사업 비교 | I2: 표 4. 국내 반도체 테스트 인터페이스 피어 실적·사업 비교
A3: ISC (095340) | 리서치 기준일 2026-04-28 | 단위는 각 표에 표시 | 삼성증권 1Q26 Review 및 사용자 제공 ZIP 기반
A4: 입력/추정 가정: 연노랑 배경 + 파란 글씨 | 계산식: 검은 글씨 | 다른 시트 연결: 초록 글씨
A5: 종목코드 | B5: 기업명 | C5: 시장 | D5: 사업 연관성 | E5: 주가 (원) | F5: 주가 기준일 | G5: Forward P/E | H5: Implied Forward EPS | I5: Include
A6: 058470 | B6: 리노공업 | C6: KOSDAQ | D6: 포고핀 테스트소켓 | E6: 72300 | F6: 46219 | G6: 28.3 | H6: =E6/G6 -> 2554.7703 | I6: Y
A7: 131290 | B7: 티에스이 | C7: KOSDAQ | D7: 프로브카드·인터페이스보드 | E7: 282500 | F7: 46219 | G7: 22.47 | H7: =E7/G7 -> 12572.319 | I7: Y
A8: 089030 | B8: 테크윙 | C8: KOSDAQ | D8: 반도체 검사장비 | E8: 49200 | F8: 46219 | G8: 15.68 | H8: =E8/G8 -> 3137.7551 | I8: Y
A9: 131970 | B9: 두산테스나 | C9: KOSDAQ | D9: 웨이퍼·패키지 테스트 | E9: 86900 | F9: 46219 | G9: 39.31 | H9: =E9/G9 -> 2210.6334 | I9: Y
A11: ZIP 패키지의 피어 원자료에는 기업별 매출·영업이익 전망치가 없으므로 확인되지 않은 실적 수치를 임의 추가하지 않았습니다. 대신 주가와 Forward P/E로 암시 Forward EPS를 수식 계산해 실적 기대를 비교합니다.

Sheet 06_재무요약
A1: 예상 재무제표 및 주당가치 요약 | B1: 예상 재무제표 및 주당가치 요약 | C1: 예상 재무제표 및 주당가치 요약 | D1: 예상 재무제표 및 주당가치 요약 | E1: 예상 재무제표 및 주당가치 요약 | F1: 예상 재무제표 및 주당가치 요약 | G1: 예상 재무제표 및 주당가치 요약 | H1: 예상 재무제표 및 주당가치 요약 | I1: 예상 재무제표 및 주당가치 요약 | J1: 예상 재무제표 및 주당가치 요약 | K1: 예상 재무제표 및 주당가치 요약 | L1: 예상 재무제표 및 주당가치 요약 | M1: 예상 재무제표 및 주당가치 요약
A2: 예상 재무제표 및 주당가치 요약 | B2: 예상 재무제표 및 주당가치 요약 | C2: 예상 재무제표 및 주당가치 요약 | D2: 예상 재무제표 및 주당가치 요약 | E2: 예상 재무제표 및 주당가치 요약 | F2: 예상 재무제표 및 주당가치 요약 | G2: 예상 재무제표 및 주당가치 요약 | H2: 예상 재무제표 및 주당가치 요약 | I2: 예상 재무제표 및 주당가치 요약 | J2: 예상 재무제표 및 주당가치 요약 | K2: 예상 재무제표 및 주당가치 요약 | L2: 예상 재무제표 및 주당가치 요약 | M2: 예상 재무제표 및 주당가치 요약
A3: ISC (095340) | 리서치 기준일 2026-04-28 | 단위는 각 표에 표시 | 삼성증권 1Q26 Review 및 사용자 제공 ZIP 기반
A4: 입력/추정 가정: 연노랑 배경 + 파란 글씨 | 계산식: 검은 글씨 | 다른 시트 연결: 초록 글씨
A5: 포괄손익계산서 (십억원) | B5: 포괄손익계산서 (십억원) | C5: 포괄손익계산서 (십억원) | D5: 포괄손익계산서 (십억원) | E5: 포괄손익계산서 (십억원) | F5: 포괄손익계산서 (십억원) | H5: 재무상태표 (십억원) | I5: 재무상태표 (십억원) | J5: 재무상태표 (십억원) | K5: 재무상태표 (십억원) | L5: 재무상태표 (십억원) | M5: 재무상태표 (십억원)
A6: 항목 | B6: 2023 | C6: 2024 | D6: 2025 | E6: 2026E | F6: 2027E | H6: 항목 | I6: 2023 | J6: 2024 | K6: 2025 | L6: 2026E | M6: 2027E
A7: 매출액 | B7: 140 | C7: 174 | D7: 220 | E7: 314 | F7: 403 | H7: 유동자산 | I7: 362 | J7: 405 | K7: 447 | L7: 480 | M7: 568
A8: 매출원가 | B8: 85 | C8: 100 | D8: 122 | E8: 166 | F8: 212 | H8: 현금 및 현금성자산 | I8: 268 | J8: 40 | K8: 80 | L8: 58 | M8: 80
A9: 매출총이익 | B9: 55 | C9: 74 | D9: 98 | E9: 148 | F9: 191 | H9: 매출채권 | I9: 21 | J9: 33 | K9: 70 | L9: 86 | M9: 111
A10: 매출총이익률 (%) | B10: 39.3 | C10: 42.6 | D10: 44.4 | E10: 47.1 | F10: 47.4 | H10: 재고자산 | I10: 15 | J10: 15 | K10: 25 | L10: 28 | M10: 33
A11: 판매 및 일반관리비 | B11: 44 | C11: 30 | D11: 38 | E11: 48 | F11: 54 | H11: 기타유동자산 | I11: 57 | J11: 317 | K11: 272 | L11: 307 | M11: 344
A12: 영업이익 | B12: 11 | C12: 45 | D12: 60 | E12: 100 | F12: 137 | H12: 비유동자산 | I12: 180 | J12: 178 | K12: 176 | L12: 223 | M12: 250
A13: 영업이익률 (%) | B13: 7.7 | C13: 25.7 | D13: 27.3 | E13: 32 | F13: 34 | H13: 투자자산 | I13: 10 | J13: 9 | K13: 6 | L13: 6 | M13: 6
A14: 영업외손익 | B14: 7 | C14: 25 | D14: 7 | E14: 12 | F14: 11 | H14: 유형자산 | I14: 93 | J14: 92 | K14: 91 | L14: 157 | M14: 186
A15: 세전이익 | B15: 18 | C15: 70 | D15: 67 | E15: 113 | F15: 148 | H15: 무형자산 | I15: 21 | J15: 18 | K15: 20 | L15: 18 | M15: 17
A16: 법인세 | B16: 4 | C16: 15 | D16: 10 | E16: 25 | F16: 33 | H16: 기타비유동자산 | I16: 56 | J16: 59 | K16: 59 | L16: 41 | M16: 41
A17: 당기순이익 | B17: 14 | C17: 55 | D17: 56 | E17: 88 | F17: 116 | H17: 자산총계 | I17: 542 | J17: 583 | K17: 622 | L17: 703 | M17: 818
A18: 지배주주순이익 | B18: 13 | C18: 55 | D18: 56 | E18: 87 | F18: 115 | H18: 유동부채 | I18: 58 | J18: 52 | K18: 83 | L18: 91 | M18: 109
... A20: EPS (원) | B20: 750 | C20: 2671 | D20: 2743 | E20: 4266 | F20: 5623 | H20: 단기차입금 | I20: 18 | J20: 0 | K20: 0 | L20: 0 | M20: 0
H21: 기타유동부채 | I21: 36 | J21: 45 | K21: 50 | L21: 26 | M21: 26
H22: 비유동부채 | I22: 10 | J22: 7 | K22: 2 | L22: 3 | M22: 3
A23: 현금흐름표 (십억원) | B23: 현금흐름표 (십억원) | C23: 현금흐름표 (십억원) | D23: 현금흐름표 (십억원) | E23: 현금흐름표 (십억원) | F23: 현금흐름표 (십억원) | H23: 부채총계 | I23: 68 | J23: 60 | K23: 85 | L23: 93 | M23: 111
A24: 항목 | B24: 2023 | C24: 2024 | D24: 2025 | E24: 2026E | F24: 2027E | H24: 지배주주지분 | I24: 473 | J24: 523 | K24: 537 | L24: 609 | M24: 705
A25: 영업활동 현금흐름 | B25: 22 | C25: 51 | D25: 42 | E25: 76 | F25: 90 | H25: 자본금 | I25: 11 | J25: 11 | K25: 11 | L25: 11 | M25: 11
A26: 당기순이익 | B26: 14 | C26: 55 | D26: 56 | E26: 88 | F26: 116 | H26: 자본잉여금 | I26: 316 | J26: 316 | K26: 290 | L26: 290 | M26: 290
A27: 비현금수익비용 | B27: 25 | C27: 7 | D27: 14 | E27: 15 | F27: 23 | H27: 이익잉여금 | I27: 173 | J27: 222 | K27: 261 | L27: 330 | M27: 426
A28: 유형자산 감가상각비 | B28: 7 | C28: 9 | D28: 9 | E28: 14 | F28: 21 | H28: 기타 | I28: -26 | J28: -26 | K28: -24 | L28: -22 | M28: -22
A29: 무형자산 상각비 | B29: 2 | C29: 1 | D29: 1 | E29: 1 | F29: 1 | H29: 비지배주주지분 | I29: 0 | J29: 0 | K29: 1 | L29: 1 | M29: 1
A30: 운전자본 변동 | B30: 0 | C30: -11 | D30: -27 | E30: -27 | F30: -48 | H30: 자본총계 | I30: 473 | J30: 523 | K30: 537 | L30: 610 | M30: 707
A31: 투자활동 현금흐름 | B31: -2 | C31: -252 | D31: 14 | E31: -80 | F31: -50
A32: 유형자산 증감 | B32: -13 | C32: -5 | D32: -5 | E32: -80 | F32: -50
A33: 장단기금융자산 증감 | B33: 2 | C33: -275 | D33: 43 | E33: 0 | F33: 0 | H33: 주당가치 및 Valuation | I33: 주당가치 및 Valuation | J33: 주당가치 및 Valuation | K33: 주당가치 및 Valuation | L33: 주당가치 및 Valuation | M33: 주당가치 및 Valuation
A34: 기타투자활동 | B34: 10 | C34: 28 | D34: -23 | E34: 0 | F34: 0 | H34: 항목 | I34: 2023 | J34: 2024 | K34: 2025 | L34: 2026E | M34: 2027E
A35: 재무활동 현금흐름 | B35: 194 | C35: -27 | D35: -17 | E35: -17 | F35: -18 | H35: EPS (원) | I35: 750 | J35: 2671 | K35: 2743 | L35: 4266 | M35: 5623
A36: 차입금 증감 | B36: 4 | C36: -23 | D36: 0 | E36: 0 | F36: 0 | H36: BPS (원) | I36: 26917 | J36: 25547 | K36: 26223 | L36: 29738 | M36: 34461
A37: 자본금 증감 | B37: 200 | C37: 0 | D37: -26 | E37: 0 | F37: 0 | H37: DPS (원) | I37: 200 | J37: 810 | K37: 850 | L37: 900 | M37: 1000
A38: 배당금 | B38: -10 | C38: -4 | D38: -17 | E38: -17 | F38: -18 | H38: P/E (x) | I38: 107.1 | J38: 27 | K38: 40.5 | L38: 56.4 | M38: 42.8
A39: 현금의 증가 | B39: 214 | C39: -228 | D39: 40 | E39: -22 | F39: 22 | H39: P/B (x) | I39: 3 | J39: 2.8 | K39: 4.2 | L39: 8.1 | M39: 7
A40: 기초현금 | B40: 54 | C40: 268 | D40: 40 | E40: 80 | F40: 58 | H40: EV/EBITDA (x) | I40: 62.6 | J40: 22 | K40: 29 | L40: 41.4 | M40: 29.5
A41: 기말현금 | B41: 268 | C41: 40 | D41: 80 | E41: 58 | F41: 80 | H41: ROE (%) | I41: 3.6 | J41: 11 | K41: 10.6 | L41: 15.2 | M41: 17.5
...

Sheet 05_피어밸류
A1: 표 5. 국내 피어 밸류에이션 비교 | B1: 표 5. 국내 피어 밸류에이션 비교 | C1: 표 5. 국내 피어 밸류에이션 비교 | D1: 표 5. 국내 피어 밸류에이션 비교 | E1: 표 5. 국내 피어 밸류에이션 비교 | F1: 표 5. 국내 피어 밸류에이션 비교 | G1: 표 5. 국내 피어 밸류에이션 비교 | H1: 표 5. 국내 피어 밸류에이션 비교 | I1: 표 5. 국내 피어 밸류에이션 비교 | J1: 표 5. 국내 피어 밸류에이션 비교
A2: 표 5. 국내 피어 밸류에이션 비교 | B2: 표 5. 국내 피어 밸류에이션 비교 | C2: 표 5. 국내 피어 밸류에이션 비교 | D2: 표 5. 국내 피어 밸류에이션 비교 | E2: 표 5. 국내 피어 밸류에이션 비교 | F2: 표 5. 국내 피어 밸류에이션 비교 | G2: 표 5. 국내 피어 밸류에이션 비교 | H2: 표 5. 국내 피어 밸류에이션 비교 | I2: 표 5. 국내 피어 밸류에이션 비교 | J2: 표 5. 국내 피어 밸류에이션 비교
A3: ISC (095340) | 리서치 기준일 2026-04-28 | 단위는 각 표에 표시 | 삼성증권 1Q26 Review 및 사용자 제공 ZIP 기반
A4: 입력/추정 가정: 연노랑 배경 + 파란 글씨 | 계산식: 검은 글씨 | 다른 시트 연결: 초록 글씨
A5: 종목코드 | B5: 기업명 | C5: 시장 | D5: 사업 연관성 | E5: 주가 | F5: 기준일 | G5: Forward P/E | H5: Include | I5: 출처 | J5: 적용 P/E
A6: 058470 | B6: 리노공업 | C6: KOSDAQ | D6: 포고핀 테스트소켓 | E6: 72300 | F6: 46219 | G6: 28.3 | H6: Y | I6: ZIP 11_Comps_Web | J6: =IF(H6="Y",G6,"") -> 28.3
A7: 131290 | B7: 티에스이 | C7: KOSDAQ | D7: 프로브카드·인터페이스보드 | E7: 282500 | F7: 46219 | G7: 22.47 | H7: Y | I7: ZIP 11_Comps_Web | J7: =IF(H7="Y",G7,"") -> 22.47
A8: 089030 | B8: 테크윙 | C8: KOSDAQ | D8: 반도체 검사장비 | E8: 49200 | F8: 46219 | G8: 15.68 | H8: Y | I8: ZIP 11_Comps_Web | J8: =IF(H8="Y",G8,"") -> 15.68
A9: 131970 | B9: 두산테스나 | C9: KOSDAQ | D9: 웨이퍼·패키지 테스트 | E9: 86900 | F9: 46219 | G9: 39.31 | H9: Y | I9: ZIP 11_Comps_Web | J9: =IF(H9="Y",G9,"") -> 39.31
A11: Peer median Forward P/E | G11: =MEDIAN(J6:J9) -> 25.385
A12: Peer average Forward P/E | G12: =AVERAGE(J6:J9) -> 26.44
A13: Peer count | G13: =COUNT(J6:J9) -> 4
A15: 선정 원칙: KOSPI/KOSDAQ 상장사 중 테스트소켓·프로브카드·검사장비·반도체 테스트 노출도가 높은 기업. Include=Y 중앙값은 국내 비교용이며, 목표주가는 삼성증권의 WinWay P/E 40% 할인 방식을 별도로 적용합니다.

Sheet 07_출처검증
A1: 출처 · 모델 검증 · 재사용 메모 | B1: 출처 · 모델 검증 · 재사용 메모 | C1: 출처 · 모델 검증 · 재사용 메모 | D1: 출처 · 모델 검증 · 재사용 메모 | E1: 출처 · 모델 검증 · 재사용 메모 | F1: 출처 · 모델 검증 · 재사용 메모 | G1: 출처 · 모델 검증 · 재사용 메모
A2: 출처 · 모델 검증 · 재사용 메모 | B2: 출처 · 모델 검증 · 재사용 메모 | C2: 출처 · 모델 검증 · 재사용 메모 | D2: 출처 · 모델 검증 · 재사용 메모 | E2: 출처 · 모델 검증 · 재사용 메모 | F2: 출처 · 모델 검증 · 재사용 메모 | G2: 출처 · 모델 검증 · 재사용 메모
A3: ISC (095340) | 리서치 기준일 2026-04-28 | 단위는 각 표에 표시 | 삼성증권 1Q26 Review 및 사용자 제공 ZIP 기반
A4: 입력/추정 가정: 연노랑 배경 + 파란 글씨 | 계산식: 검은 글씨 | 다른 시트 연결: 초록 글씨
A5: 출처 | B5: 출처 | C5: 출처 | D5: 출처 | E5: 출처 | F5: 출처 | G5: 출처
A6: ID | B6: 대상 | C6: 페이지/범위 | D6: 원문 파일 또는 URL | E6: 기준일 | F6: 기관 | G6: 비고
A7: SRC-01 | B7: 패키지 기존 모델 | C7: 전체 | D7: C:\Users\KDA 24\Documents\Codex\2026-07-20\referenced-chatgpt-conversation-this-is-untrusted\work\isc_package\04_Model\ISC_095340_Peer_PER_Valuation.xlsx | E7: 46223 | F7: 사용자 제공 ZIP | G7: 국내 피어·기존 산식 참고
A8: SRC-02 | B8: 1Q26 Review | C8: p.1-3 | D8: C:\Users\KDA 24\Documents\Codex\2026-07-20\referenced-chatgpt-conversation-this-is-untrusted\work\isc_package\02_Research\2026-04-28_Samsung_Securities.pdf | E8: 46140 | F8: 삼성증권 | G8: 분기 전망·재무제표·WinWay 40% 할인
A9: SRC-03 | B9: 4Q25 Review | C9: p.1-6 | D9: C:\Users\KDA 24\Documents\Codex\2026-07-20\referenced-chatgpt-conversation-this-is-untrusted\work\isc_package\02_Research\2026_Meritz_Company_Brief.pdf | E9: 46062 | F9: 메리츠증권 | G9: 추정 변경·글로벌 피어 방식
A10: SRC-04 | B10: 기업 브리프 | C10: p.1-6 | D10: C:\Users\KDA 24\Documents\Codex\2026-07-20\referenced-chatgpt-conversation-this-is-untrusted\work\isc_package\02_Research\2026-02-10_Korea_Investment.pdf | E10: 46063 | F10: 한국투자증권 | G10: 사업 전망·목표주가
A11: SRC-05 | B11: IR Book | C11: 전체 | D11: C:\Users\KDA 24\Documents\Codex\2026-07-20\referenced-chatgpt-conversation-this-is-untrusted\work\isc_package\03_IR\2026_IR_Book.pdf | E11: 46023 | F11: ISC | G11: 애플리케이션·CAPEX
A12: SRC-06 | B12: 2025 사업보고서 | C12: DART | D12: https://dart.fss.or.kr/dsaf001/main.do?rcpNo=20260318000018 | E12: 46099 | F12: 금융감독원 DART | G12: 2025 확정 실적
A13: SRC-07 | B13: 피어 원자료 | C13: 11_Comps_Web | D13: C:\Users\KDA 24\Documents\Codex\2026-07-20\referenced-chatgpt-conversation-this-is-untrusted\work\isc_package\04_Model\ISC_095340_Peer_PER_Valuation.xlsx | E13: 46223 | F13: 사용자 제공 ZIP | G13: KOSPI/KOSDAQ만 포함
A16: 검증 체크 | B16: 검증 체크 | C16: 검증 체크 | D16: 검증 체크 | E16: 검증 체크 | F16: 검증 체크 | G16: 검증 체크
A17: 검증항목 | B17: 실제값 | C17: 기대값 | D17: 차이 | E17: 허용오차 | F17: 상태 | G17: 비고
A18: WinWay 적용비율 | B18: =1-'03_목표주가'!B8 -> 0.6 | C18: 0.6 | D18: =B18-C18 -> 0 | E18: 0.0001 | F18: =IF(ABS(D18)<=E18,"OK","CHECK") -> OK | G18: 1-40% 할인율
A19: 적용 Target P/E | B19: ='03_목표주가'!B9 -> 53.352303 | C19: 53.352303 | D19: =B19-C19 -> -2.0000357e-10 | E19: 0.001 | F19: =IF(ABS(D19)<=E19,"OK","CHECK") -> OK | G19: WinWay P/E × 60%
A20: 제시 목표주가 | B20: ='03_목표주가'!B11 -> 300000 | C20: 300000 | D20: =B20-C20 -> 0 | E20: 1 | F20: =IF(ABS(D20)<=E20,"OK","CHECK") -> OK | G20: EPS × Target P/E, 1,000원 반올림
A21: FY26 분기 매출 합계 | B21: =SUM('01_실적추이'!F6:I6) -> 314.2 | C21: 314.2 | D21: =B21-C21 -> 0 | E21: 0.1 | F21: =IF(ABS(D21)<=E21,"OK","CHECK") -> OK | G21: 1Q26~4Q26
A22: FY26 분기 영업이익 합계 | B22: =SUM('01_실적추이'!F20:I20) -> 100.5 | C22: 100.4 | D22: =B22-C22 -> 0.1 | E22: 0.2 | F22: =IF(ABS(D22)<=E22,"OK","CHECK") -> OK | G22: 표 반올림 차이 허용
A23: FY27E EPS | B23: ='03_목표주가'!B6 -> 5623 | C23: 5623 | D23: =B23-C23 -> 0 | E23: 0.1 | F23: =IF(ABS(D23)<=E23,"OK","CHECK") -> OK | G23: 삼성증권 FY27E
A24: 국내 피어 개수 | B24: ='05_피어밸류'!G13 -> 4 | C24: 4 | D24: =B24-C24 -> 0 | E24: 0 | F24: =IF(ABS(D24)<=E24,"OK","CHECK") -> OK | G24: 국내 비교용
A27: 재사용 메모 | B27: 재사용 메모 | C27: 재사용 메모 | D27: 재사용 메모 | E27: 재사용 메모 | F27: 재사용 메모 | G27: 재사용 메모
A28: 솔브레인 파일과 동일한 시트명·순서를 사용해 기업 간 비교가 가능합니다.
A29: ISC 고유 Driver는 데이터센터·스마트폰·기타 애플리케이션 매출과 SLT 비중입니다.
A30: 피어 실적 수치가 ZIP에 없는 경우 공란을 임의 추정하지 않고, 주가/PER 기반 암시 EPS만 계산했습니다.
A31: 시장 데이터 갱신 시 04_피어실적·05_피어밸류·03_목표주가를 함께 검토하고 모든 체크가 OK인지 확인합니다.

Sheet 08_Forward_EPS
A1: 통합 Forward EPS 추정 모델 | B1: 통합 Forward EPS 추정 모델 | C1: 통합 Forward EPS 추정 모델 | D1: 통합 Forward EPS 추정 모델 | E1: 통합 Forward EPS 추정 모델 | F1: 통합 Forward EPS 추정 모델 | G1: 통합 Forward EPS 추정 모델 | H1: 통합 Forward EPS 추정 모델
A2: 통합 Forward EPS 추정 모델 | B2: 통합 Forward EPS 추정 모델 | C2: 통합 Forward EPS 추정 모델 | D2: 통합 Forward EPS 추정 모델 | E2: 통합 Forward EPS 추정 모델 | F2: 통합 Forward EPS 추정 모델 | G2: 통합 Forward EPS 추정 모델 | H2: 통합 Forward EPS 추정 모델
A3: ISC (095340) | 리서치 기준일 2026-04-28 | 단위는 각 표에 표시 | 삼성증권 1Q26 Review 및 사용자 제공 ZIP 기반
A4: 입력/추정 가정: 연노랑 배경 + 파란 글씨 | 계산식: 검은 글씨 | 다른 시트 연결: 초록 글씨
A5: 리포트용 핵심 출력 | B5: 리포트용 핵심 출력 | C5: 리포트용 핵심 출력 | D5: 리포트용 핵심 출력 | E5: 리포트용 핵심 출력 | F5: 리포트용 핵심 출력 | G5: 리포트용 핵심 출력 | H5: 리포트용 핵심 출력
A6: FY26E 매출액 (십억원) | B6: =C15 -> 314.2 | D6: FY27E 매출액 (십억원) | E6: =D15 -> 402.176
A7: FY26E 영업이익 (십억원) | B7: =C25 -> 100.4 | D7: FY27E 영업이익 (십억원) | E7: =D25 -> 136.68988
A8: FY26E Forward EPS (원) | B8: =C36 -> 4266 | D8: FY27E Forward EPS (원) | E8: =D36 -> 5618.4737
A9: FY26E 영업이익률 | B9: =C26 -> 0.31954169 | D9: FY27E 영업이익률 | E9: =D26 -> 0.33987578
A11: 입력 방법: 노란색·파란 글씨 셀의 성장률/비율/주식수를 수정하면 바로 위 계산 행과 Forward EPS가 즉시 갱신됩니다. 2028E는 서비스 시나리오용 사용자 가정입니다.
A13: 매출액부터 Forward EPS까지 통합 추정 | B13: 매출액부터 Forward EPS까지 통합 추정 | C13: 매출액부터 Forward EPS까지 통합 추정 | D13: 매출액부터 Forward EPS까지 통합 추정 | E13: 매출액부터 Forward EPS까지 통합 추정 | F13: 매출액부터 Forward EPS까지 통합 추정 | G13: 매출액부터 Forward EPS까지 통합 추정 | H13: 매출액부터 Forward EPS까지 통합 추정
A14: 손익계산서 / Driver | B14: 2025A | C14: 2026E | D14: 2027E | E14: 2028E | F14: 산식 / 입력 기준 | G14: 구분 | H14: 리포트 활용
A15: 매출액 (십억원) | B15: 220.2 | C15: =B15*(1+C16) -> 314.2 | D15: =C15*(1+D16) -> 402.176 | E15: =D15*(1+E16) -> 482.6112 | F15: 전년도 매출 × (1+성장률) | G15: 계산 | H15: 실적 추이·전망
A16: 매출 성장률 | C16: 0.42688465 | D16: 0.28 | E16: 0.2 | F16: 사용자 입력 | G16: Driver | H16: 매출 성장 가정
A18: 매출원가 (십억원) | B18: 122.5 | C18: =C15*C19 -> 166.2 | D18: =D15*D19 -> 211.72943 | E18: =E15*E19 -> 253.37088 | F18: 매출액 × 원가율 | G18: 계산 | H18: 손익계산서
A19: 매출원가율 | B19: 0.55631244 | C19: 0.52896244 | D19: 0.52645963 | E19: 0.525 | F19: 사용자 입력 | G19: Driver | H19: 제품 믹스·원가 가정
A20: 매출총이익 (십억원) | B20: =B15-B18 -> 97.7 | C20: =C15-C18 -> 148 | D20: =D15-D18 -> 190.44657 | E20: =E15-E18 -> 229.24032 | F20: 매출액-매출원가 | G20: 계산 | H20: 손익계산서
A21: 매출총이익률 | B21: =B20/B15 -> 0.44368756 | C21: =C20/C15 -> 0.47103756 | D21: =D20/D15 -> 0.47354037 | E21: =E20/E15 -> 0.475 | F21: 매출총이익÷매출액 | G21: 계산 | H21: 수익성
A23: 판매 및 일반관리비 (십억원) | B23: 37.7 | C23: =C15*C24 -> 47.6 | D23: =D15*D24 -> 53.756693 | E23: =E15*E24 -> 62.739456 | F23: 매출액 × 판관비율 | G23: 계산 | H23: 손익계산서
A24: 판관비율 | B24: 0.17120799 | C24: 0.15149586 | D24: 0.1336646 | E24: 0.13 | F24: 사용자 입력 | G24: Driver | H24: 비용 가정
A25: 영업이익 (십억원) | B25: 60.1 | C25: =C20-C23 -> 100.4 | D25: =D20-D23 -> 136.68988 | E25: =E20-E23 -> 166.50086 | F25: 매출총이익-판관비 | G25: 계산 | H25: 손익계산서
A26: 영업이익률 | B26: =B25/B15 -> 0.2729337 | C26: =C25/C15 -> 0.31954169 | D26: =D25/D15 -> 0.33987578 | E26: =E25/E15 -> 0.345 | F26: 영업이익÷매출액 | G26: 계산 | H26: 수익성
A28: 영업외손익 (십억원) | B28: 6.5 | C28: =C15*C29 -> 12.2 | D28: =D15*D29 -> 11.290904 | E28: =E15*E29 -> 12.06528 | F28: 매출액 × 영업외손익률 | G28: 계산 | H28: 손익계산서
A29: 영업외손익률 | B29: 0.029518619 | C29: 0.038828771 | D29: 0.028074534 | E29: 0.025 | F29: 사용자 입력 | G29: Driver | H29: 금융·기타손익 가정
A30: 세전이익 (십억원) | B30: 66.6 | C30: =C25+C28 -> 112.6 | D30: =D25+D28 -> 147.98078 | E30: =E25+E28 -> 178.56614 | F30: 영업이익+영업외손익 | G30: 계산 | H30: 손익계산서
A32: 지배주주순이익 (십억원) | B32: 56.1 | C32: =C30*(1-C33) -> 87.3 | D32: =D30*(1-D33) -> 115.00735 | E32: =E30*(1-E33) -> 139.28159 | F32: 세전이익 × (1-누수율) | G32: 계산 | H32: EPS 분자
A33: 실효세율·비지배 누수율 | B33: 0.15765766 | C33: 0.22468917 | D33: 0.22282242 | E33: 0.22 | F33: 사용자 입력 | G33: Driver | H33: 세금·비지배 가정
A35: 희석주식수 (백만주) | B35: 20.45206 | C35: 20.464135 | D35: 20.4695 | E35: 20.4695 | F35: 사용자 입력 | G35: Driver | H35: EPS 분모
A36: Forward EPS (원) | B36: 2743 | C36: =C32*1000/C35 -> 4266 | D36: =D32*1000/D35 -> 5618.4737 | E36: =E32*1000/E35 -> 6804.3475 | F36: 지배순이익×1,000÷주식수 | G36: 계산 | H36: 목표주가 산정
A37: EPS 성장률 | C37: =C36/B36-1 -> 0.5552315 | D37: =D36/C36-1 -> 0.31703555 | E37: =E36/D36-1 -> 0.2110669 | F37: 당해 EPS÷전년 EPS-1 | G37: 계산 | H37: 이익 성장률
A40: 모델 체크 | B40: 모델 체크 | C40: 모델 체크 | D40: 모델 체크 | E40: 모델 체크 | F40: 모델 체크 | G40: 모델 체크 | H40: 모델 체크
A41: 검증항목 | B41: 차이 | C41: 상태 | D41: 설명
A42: FY26E 매출액 vs 리포트 | B42: =C15-314.2 -> 0 | C42: =IF(ABS(B42)<=0.1,"OK","CHECK") -> OK | D42: 314.2십억원
A43: FY27E 매출액 vs 리포트 | B43: =D15-402.5 -> -0.324 | C43: =IF(ABS(B43)<=0.1,"OK","CHECK") -> CHECK | D43: 402.5십억원
A44: FY26E EPS vs 리포트 | B44: =C36-4266 -> 0 | C44: =IF(ABS(B44)<=0.5,"OK","CHECK") -> OK | D44: 4,266원
A45: FY27E EPS vs 리포트 | B45: =D36-5623 -> -4.5263404 | C45: =IF(ABS(B45)<=0.5,"OK","CHECK") -> CHECK | D45: 5,623원

Sheet 08-01
A1: 통합 Forward EPS 추정 모델 | B1: 통합 Forward EPS 추정 모델 | C1: 통합 Forward EPS 추정 모델 | D1: 통합 Forward EPS 추정 모델 | E1: 통합 Forward EPS 추정 모델 | F1: 통합 Forward EPS 추정 모델 | G1: 통합 Forward EPS 추정 모델 | H1: 통합 Forward EPS 추정 모델
A2: 통합 Forward EPS 추정 모델 | B2: 통합 Forward EPS 추정 모델 | C2: 통합 Forward EPS 추정 모델 | D2: 통합 Forward EPS 추정 모델 | E2: 통합 Forward EPS 추정 모델 | F2: 통합 Forward EPS 추정 모델 | G2: 통합 Forward EPS 추정 모델 | H2: 통합 Forward EPS 추정 모델
A3: ISC (095340) | 리서치 기준일 2026-04-28 | 단위는 각 표에 표시 | 삼성증권 1Q26 Review 및 사용자 제공 ZIP 기반
A4: 입력/추정 가정: 연노랑 배경 + 파란 글씨 | 계산식: 검은 글씨 | 다른 시트 연결: 초록 글씨
A6: 입력 방법: 노란색·파란 글씨 셀의 성장률/비율/주식수를 수정하면 바로 위 계산 행과 Forward EPS가 즉시 갱신됩니다. 2028E는 서비스 시나리오용 사용자 가정입니다.
A8: 매출액부터 Forward EPS까지 통합 추정 | B8: 매출액부터 Forward EPS까지 통합 추정 | C8: 매출액부터 Forward EPS까지 통합 추정 | D8: 매출액부터 Forward EPS까지 통합 추정 | E8: 매출액부터 Forward EPS까지 통합 추정 | F8: 매출액부터 Forward EPS까지 통합 추정 | G8: 매출액부터 Forward EPS까지 통합 추정 | H8: 매출액부터 Forward EPS까지 통합 추정
A9: 손익계산서 / Driver | B9: 2025A | C9: 2026E | D9: 2027E | E9: 2028E
A10: 매출액 (십억원) | B10: 220.2 | C10: =B10*(1+C11) -> 314.2 | D10: =C10*(1+D11) -> 402.176 | E10: =D10*(1+E11) -> 482.6112
A11: 매출 성장률 | C11: 0.42688465 | D11: 0.28 | E11: 0.2
A12: 매출원가 (십억원) | B12: 122.5 | C12: =C10*C13 -> 166.2 | D12: =D10*D13 -> 211.72943 | E12: =E10*E13 -> 253.37088
A13: 매출원가율 | B13: 0.55631244 | C13: 0.52896244 | D13: 0.52645963 | E13: 0.525
A14: 매출총이익 (십억원) | B14: =B10-B12 -> 97.7 | C14: =C10-C12 -> 148 | D14: =D10-D12 -> 190.44657 | E14: =E10-E12 -> 229.24032
A15: 매출총이익률 | B15: =B14/B10 -> 0.44368756 | C15: =C14/C10 -> 0.47103756 | D15: =D14/D10 -> 0.47354037 | E15: =E14/E10 -> 0.475
A16: 판매 및 일반관리비 (십억원) | B16: 37.7 | C16: =C10*C17 -> 47.6 | D16: =D10*D17 -> 53.756693 | E16: =E10*E17 -> 62.739456
A17: 판관비율 | B17: 0.17120799 | C17: 0.15149586 | D17: 0.1336646 | E17: 0.13
A18: 영업이익 (십억원) | B18: 60.1 | C18: =C14-C16 -> 100.4 | D18: =D14-D16 -> 136.68988 | E18: =E14-E16 -> 166.50086
A19: 영업이익률 | B19: =B18/B10 -> 0.2729337 | C19: =C18/C10 -> 0.31954169 | D19: =D18/D10 -> 0.33987578 | E19: =E18/E10 -> 0.345
A20: 영업외손익 (십억원) | B20: 6.5 | C20: =C10*C21 -> 12.2 | D20: =D10*D21 -> 11.290904 | E20: =E10*E21 -> 12.06528
A21: 영업외손익률 | B21: 0.029518619 | C21: 0.038828771 | D21: 0.028074534 | E21: 0.025
A22: 세전이익 (십억원) | B22: 66.6 | C22: =C18+C20 -> 112.6 | D22: =D18+D20 -> 147.98078 | E22: =E18+E20 -> 178.56614
A23: 지배주주순이익 (십억원) | B23: 56.1 | C23: =C22*(1-C24) -> 87.3 | D23: =D22*(1-D24) -> 115.00735 | E23: =E22*(1-E24) -> 139.28159
A24: 실효세율·비지배 누수율 | B24: 0.15765766 | C24: 0.22468917 | D24: 0.22282242 | E24: 0.22
A25: 희석주식수 (백만주) | B25: 20.45206 | C25: 20.464135 | D25: 20.4695 | E25: 20.4695
A26: Forward EPS (원) | B26: 2743 | C26: =C23*1000/C25 -> 4266 | D26: =D23*1000/D25 -> 5618.4737 | E26: =E23*1000/E25 -> 6804.3475
A27: EPS 성장률 | C27: =C26/B26-1 -> 0.5552315 | D27: =D26/C26-1 -> 0.31703555 | E27: =E26/D26-1 -> 0.2110669

Sheet 09_Target_PER
A1: Target PER 선정 및 목표주가 모델 | B1: Target PER 선정 및 목표주가 모델 | C1: Target PER 선정 및 목표주가 모델 | D1: Target PER 선정 및 목표주가 모델 | E1: Target PER 선정 및 목표주가 모델 | F1: Target PER 선정 및 목표주가 모델 | G1: Target PER 선정 및 목표주가 모델 | H1: Target PER 선정 및 목표주가 모델 | I1: Target PER 선정 및 목표주가 모델
A2: Target PER 선정 및 목표주가 모델 | B2: Target PER 선정 및 목표주가 모델 | C2: Target PER 선정 및 목표주가 모델 | D2: Target PER 선정 및 목표주가 모델 | E2: Target PER 선정 및 목표주가 모델 | F2: Target PER 선정 및 목표주가 모델 | G2: Target PER 선정 및 목표주가 모델 | H2: Target PER 선정 및 목표주가 모델 | I2: Target PER 선정 및 목표주가 모델
A3: ISC (095340) | 리서치 기준일 2026-04-28 | 단위는 각 표에 표시 | 삼성증권 1Q26 Review 및 사용자 제공 ZIP 기반
A4: 입력/추정 가정: 연노랑 배경 + 파란 글씨 | 계산식: 검은 글씨 | 다른 시트 연결: 초록 글씨
A5: Target PER 선택 로직 | B5: Target PER 선택 로직 | C5: Target PER 선택 로직 | D5: Target PER 선택 로직 | E5: Target PER 선택 로직 | F5: Target PER 선택 로직 | G5: Target PER 선택 로직 | H5: Target PER 선택 로직 | I5: Target PER 선택 로직
A6: 선정 방식 | B6: 특정 피어 조정 | D6: 현재 선택: WinWay 88.92배에서 40% 할인 → Target P/E 53.35배
A7: Forward EPS | B7: ='08_Forward_EPS'!D36 -> 5618.4737 | D7: Forward EPS는 08_Forward_EPS의 FY27E EPS와 직접 연결됩니다.
A8: 선택 피어 | B8: WinWay | D8: 선정 방식을 바꾸면 국내 피어 평균·중앙값 또는 직접 입력값이 즉시 반영됩니다.
A9: 선택 피어 P/E | B9: =INDEX(D22:D26,MATCH(B8,A22:A26,0)) -> 88.920505 | D9: 특정 피어의 시장 P/E가 갱신되면 B9와 할인/프리미엄 B10을 함께 검토하십시오.
A10: 할인/프리미엄 | B10: -0.4
A11: 피어 평균 P/E | B11: =AVERAGE(G22:G26) -> 26.44
A12: 피어 중앙값 P/E | B12: =MEDIAN(G22:G26) -> 25.385
A13: 직접 입력 P/E | B13: 53.352303
A14: 도출 Target P/E | B14: =IF(B6="특정 피어 조정",B9*(1+B10),IF(B6="피어 평균",B11,IF(B6="피어 중앙값",B12,B13))) -> 53.352303
A15: 목표주가 (원) | B15: =ROUND(B7*B14,-3) -> 300000
A16: 현재주가 (원) | B16: 240500
A17: 상승여력 | B17: =B15/B16-1 -> 0.24740125
A20: 피어 정보 및 참고 멀티플 | B20: 피어 정보 및 참고 멀티플 | C20: 피어 정보 및 참고 멀티플 | D20: 피어 정보 및 참고 멀티플 | E20: 피어 정보 및 참고 멀티플 | F20: 피어 정보 및 참고 멀티플 | G20: 피어 정보 및 참고 멀티플 | H20: 피어 정보 및 참고 멀티플 | I20: 피어 정보 및 참고 멀티플
A21: 기업명 | B21: 시장 | C21: 사업 연관성 | D21: 기준 P/E | E21: Include | F21: 조정률 | G21: 적용 P/E | H21: 출처 | I21: 비고
A22: WinWay | B22: TWSE | C22: 고성능 테스트소켓 | D22: 88.920505 | E22: N | F22: -0.4 | G22: =IF(E22="Y",D22*(1+F22),"") | H22: 삼성증권 1Q26 Review | I22: 목표주가에서 역산
A23: 리노공업 | B23: KOSDAQ | C23: 포고핀 테스트소켓 | D23: 28.3 | E23: Y | F23: 0 | G23: =IF(E23="Y",D23*(1+F23),"") -> 28.3 | H23: ZIP 11_Comps_Web | I23: 국내 비교
A24: 티에스이 | B24: KOSDAQ | C24: 프로브카드·인터페이스보드 | D24: 22.47 | E24: Y | F24: 0 | G24: =IF(E24="Y",D24*(1+F24),"") -> 22.47 | H24: ZIP 11_Comps_Web | I24: 국내 비교
A25: 테크윙 | B25: KOSDAQ | C25: 반도체 검사장비 | D25: 15.68 | E25: Y | F25: 0 | G25: =IF(E25="Y",D25*(1+F25),"") -> 15.68 | H25: ZIP 11_Comps_Web | I25: 국내 비교
A26: 두산테스나 | B26: KOSDAQ | C26: 웨이퍼·패키지 테스트 | D26: 39.31 | E26: Y | F26: 0 | G26: =IF(E26="Y",D26*(1+F26),"") -> 39.31 | H26: ZIP 11_Comps_Web | I26: 국내 비교
A29: 선정 방식 가이드 | B29: 선정 방식 가이드 | C29: 선정 방식 가이드 | D29: 선정 방식 가이드 | E29: 선정 방식 가이드 | F29: 선정 방식 가이드 | G29: 선정 방식 가이드 | H29: 선정 방식 가이드 | I29: 선정 방식 가이드
A30: 특정 피어 조정: 리포트가 WinWay 등 특정 경쟁사의 멀티플에 할인/프리미엄을 적용할 때 사용
A31: 피어 평균: Include=Y 기업의 조정 후 P/E 평균을 사용
A32: 피어 중앙값: 이상치 영향을 낮추기 위해 Include=Y 기업의 조정 후 P/E 중앙값을 사용
A33: 직접 입력: 과거 밴드·산업 사이클·정성 판단을 반영한 애널리스트 승인 P/E를 사용
A36: Valuation 체크 | B36: Valuation 체크 | C36: Valuation 체크 | D36: Valuation 체크 | E36: Valuation 체크 | F36: Valuation 체크 | G36: Valuation 체크 | H36: Valuation 체크 | I36: Valuation 체크
A37: 검증항목 | B37: 실제값 | C37: 기대값 | D37: 차이 | E37: 상태 | F37: 설명
A38: FY27E EPS 연결 | B38: =B7 -> 5618.4737 | C38: 5623 | D38: =B38-C38 -> -4.5263404 | E38: =IF(ABS(D38)<=0.5,"OK","CHECK") -> CHECK | F38: 08_Forward_EPS 연결
A39: Target P/E | B39: =B14 -> 53.352303 | C39: 53.352303 | D39: =B39-C39 -> -2.0000357e-10 | E39: =IF(ABS(D39)<=0.001,"OK","CHECK") -> OK | F39: WinWay 40% 할인
A40: 목표주가 | B40: =B15 -> 300000 | C40: 300000 | D40: =B40-C40 -> 0 | E40: =IF(ABS(D40)<=1,"OK","CHECK") -> OK | F40: EPS × Target P/E
