Workbook

Sheet 00_사용안내
B1: 대덕전자 (353200) Valuation Workbook
B2: 원자료: 하나증권 「대덕전자 (353200) — 기판 맹수, 앙!」 4Q25 Earnings Review, 2026.01.30, Analyst 김민경
A4: 1. 서식 규칙 (Formatting convention)
B5: 구분 | C5: 서식 | D5: 설명
B6: 애널리스트 입력 칸 | C6: 연노랑 바탕 + 파란 글씨 + 굵은 청록 테두리 | D6: 서비스가 사용자에게 입력받을 칸입니다. 다음 분기·연도 추정치와 밸류에이션 가정(비교 P/E·타겟 멀티플)만 여기에 들어갑니다. 여기만 고치면 실적 추정·목표주가·상승여력이 전부 다시 계산됩니다. (M1·M2 시트)
B7: 공시·시장 자동 수집값 | C7: 연청회색 바탕 + 파란 글씨 | D7: 과거 확정 실적, 발행주식수, 현재주가처럼 서비스가 공시·시장 데이터에서 알아서 끌어오는 값입니다. 형식상 하드코딩이지만 사용자 입력 대상이 아니므로 노란 칸과 구분해 두었습니다.
B8: 보고서 원문 전사값 | C8: 파란 글씨 (추정치 열은 연청회색 음영) | D8: 하나증권 보고서에 인쇄된 숫자를 그대로 옮긴 값입니다. 추정 재무제표의 2025F~2027F 열은 가독성을 위해 연청회색 음영을 추가합니다.
B9: 수식 계산값 | C9: 검정 글씨 | D9: 같은 시트 안의 값으로 계산된 결과입니다.
B10: 다른 시트 참조값 | C10: 초록 글씨 | D10: 다른 시트를 참조해 계산된 결과입니다.
B11: 확보하지 못한 구간 | C11: 진한 회색 바탕 | D11: DART·리포트 어디에서도 값을 찾지 못한 칸입니다. 임의로 추정해 넣지 않았습니다.
B12: 차트 이미지 판독(근사) | C12: 옅은 주황 글씨, 기울임 | D12: 리포트에 표는 없고 차트만 있는 구간(도표4·5의 1Q21~4Q23)을 차트 이미지의 눈금을 읽어 근사한 값입니다. 연간 합계·YoY% 로 역산 가능한 구간은 우선 그 방법을 쓰고, 그래도 안 되는 21~23년만 이 방식을 썼습니다.
A14: 2. 시트 구성
B15: 시트 | C15: 원문 위치 | D15: 내용
B16: M1_실적추정_모델 | C16: (서비스 화면) | D16: 실적 추정의 유일한 입력 원천. 세그먼트 매출은 Substrate PKG → Memory/Logic → MLB → Flexible 구조로 표시하고, Substrate PKG와 매출액 계는 자동 계산합니다.
B17: M2_목표주가_타겟멀티플 | C17: (분석용 파생) | D17: Target P/E 적용 목표주가·상승여력. EPS 기준과 밸류에이션 방식은 드롭다운으로 선택
B18: M3_민감도분석 | C18: (분석용 파생) | D18: M2의 EPS·P/E를 자동 참조하는 목표주가 민감도. 이 시트에는 직접 입력 셀이 없습니다.
B19: 01_p1_투자의견 | C19: p.1 표지 | D19: 투자의견·목표주가·현재주가
B20: 01A_p1_KeyData | C20: p.1 Key Data | D20: 시장지표·주가밴드·시가총액·주식수·주요주주
B21: 02_p1_Consensus | C21: p.1 Consensus Data | D21: 시장 컨센서스 (2025·2026)
B22: 03_p1_주가추이 | C22: p.1 Stock Price | D22: 표지 주가 차트 대체
B23: 04_p1_FinancialData | C23: p.1 Financial Data | D23: 요약 투자지표
B24: 05_도표1_Valuation | C24: 도표 1 | D24: 밸류에이션
B25: 06_도표2_PER_Band | C25: 도표 2 | D25: 12MF P/E Band 배수
B26: 07_도표3_PBR_Band | C26: 도표 3 | D26: 12MF P/B Band 배수
... B38: Z_출처_공시_리서치 | C38: (부록) | D38: 출처, 미확보 구간, DART 접수번호
A40: 3. 읽을 때 유의사항
B41: • | C41: 보고서 본문의 줄글은 제외했고, 표에 인쇄된 수치와 차트만 시트로 옮겼습니다.
B42: • | C42: 표지의 투자의견과 Key Data도 각각 별도 시트로 구분했습니다.
B43: • | C43: M3 민감도분석은 입력 시트가 아닙니다. M2에서 EPS 또는 P/E를 변경하면 자동으로 갱신됩니다.
B44: • | C44: 추정 재무제표의 2025F~2027F 셀은 연청회색 음영이며, 원문 전사값은 파란 글씨·수식은 검정·다른 시트 연결은 초록 글씨입니다.
B45: • | C45: 도표4·도표5 차트 판독 근사값은 주황 기울임체로 표시했습니다.
B46: • | C46: 모든 핵심 수식과 참조는 최종 파일에서 오류값이 없는지 다시 검사했습니다.

Sheet M1_실적추정_모델
A1: 표 1. 대덕전자 실적 추정 모델 — 세그먼트 매출부터 EPS까지
A2: 대덕전자 (353200) | 4Q25 Earnings Review 기준 | 단위: 각 표 참조
A3: 노랑=입력, 연청=자동/계산, 초록=타 시트 연결, 파랑글씨=하드코딩
A5: ⓞ 공통 가정
A6: 항목 | B6: 입력값 | C6: 단위 | D6: 비고
A7: 발행주식수 | B7: 49416.9 | C7: 천주 | D7: 공시 자동 수집값 (사용자 입력 대상 아님). 01A_p1_KeyData 시트의 발행주식수, 2026.01.29 기준. 주당지표 계산의 분모입니다.
A9: ① 세그먼트별 분기 매출 (사용자 입력) — Substrate PKG는 Memory·Logic의 소계입니다
A10: 항목 | B10: 1Q25 | C10: 2Q25 | D10: 3Q25 | E10: 4Q25 | F10: 1Q26F | G10: 2Q26F | H10: 3Q26F | I10: 4Q26F | J10: 2025 | K10: 2026F | L10: 2027F
A11: Substrate PKG | B11: =B12+B13 -> 176.6 | C11: =C12+C13 -> 207.8 | D11: =D12+D13 -> 243.8 | E11: =E12+E13 -> 273.7 | F11: =F12+F13 -> 283.9 | G11: =G12+G13 -> 296.9 | H11: =H12+H13 -> 311.6 | I11: =I12+I13 -> 308.8 | ... L11: =L12+L13 -> 1343.3
A12: -Memory | B12: 101.3 | C12: 127.1 | D12: 158 | E12: 160.5 | F12: 162.1 | G12: 168.3 | H12: 174.6 | I12: 168.7 | J12: =SUM(B12:E12) -> 546.9 | K12: =SUM(F12:I12) -> 673.7 | L12: 773.6
A13: -Logic | B13: 75.3 | C13: 80.7 | D13: 85.8 | E13: 113.2 | F13: 121.8 | G13: 128.6 | H13: 137 | I13: 140.1 | J13: =SUM(B13:E13) -> 355 | K13: =SUM(F13:I13) -> 527.5 | L13: 569.7
A14: MLB | B14: 38.8 | C14: 37.7 | D14: 42.4 | E14: 44.2 | F14: 46.1 | G14: 57.1 | H14: 86 | I14: 95.1 | J14: =SUM(B14:E14) -> 163.1 | K14: =SUM(F14:I14) -> 284.3 | L14: 290
A15: Flexible | B15: 0 | C15: 0.3 | D15: 0 | E15: 0 | F15: 0 | G15: 0 | H15: 0 | I15: 0 | J15: =SUM(B15:E15) -> 0.3 | K15: =SUM(F15:I15) -> 0 | L15: 0
A16: 매출액 (계) | B16: =B11+B14+B15 -> 215.4 | C16: =C11+C14+C15 -> 245.8 | D16: =D11+D14+D15 -> 286.2 | E16: =E11+E14+E15 -> 317.9 | F16: =F11+F14+F15 -> 330 | G16: =G11+G14+G15 -> 354 | H16: =H11+H14+H15 -> 397.6 | I16: =I11+I14+I15 -> 403.9 | ... L16: =L11+L14+L15 -> 1633.3
A17: YoY | B17: =B16/B44-1 -> 0.0027932961 | C17: =C16/C44-1 -> 0.031472933 | D17: =D16/D44-1 -> 0.22990976 | E17: =E16/E44-1 -> 0.54021318 | F17: =F16/B16-1 -> 0.53203343 | G17: =G16/C16-1 -> 0.44019528 | H17: =H16/D16-1 -> 0.38923829 | I17: =I16/E16-1 -> 0.27052532 | J17: =J16/$C$32-1 -> 0.19414864 | K17: =K16/J16-1 -> 0.39444288 | L17: =L16/K16-1 -> 0.099495119 | M17: %
A18: QoQ | B18: =B16/E44-1 -> 0.043604651 | C18: =C16/B16-1 -> 0.14113278 | D18: =D16/C16-1 -> 0.16436127 | E18: =E16/D16-1 -> 0.11076171 | F18: =F16/E16-1 -> 0.038062284 | G18: =G16/F16-1 -> 0.072727273 | H18: =H16/G16-1 -> 0.12316384 | I18: =I16/H16-1 -> 0.01584507 | M18: %
A20: ② 영업이익
A21: 영업이익 | B21: -6.2 | C21: 1.9 | D21: 24.4 | E21: 29 | F21: 40.2 | G21: 43 | H21: 48.4 | I21: 48.4 | J21: =SUM(B21:E21) -> 49.1 | K21: =SUM(F21:I21) -> 180 | L21: 218.3
A22: OPM | B22: =B21/B16 -> -0.028783658 | C22: =C21/C16 -> 0.0077298617 | D22: =D21/D16 -> 0.085255066 | E22: =E21/E16 -> 0.091223655 | F22: =F21/F16 -> 0.12181818 | G22: =G21/G16 -> 0.12146893 | H22: =H21/H16 -> 0.12173038 | I22: =I21/I16 -> 0.11983164 | ... L22: =L21/L16 -> 0.13365579
A24: ③ 분기 세전이익·지배주주순이익 자동 배분
A25: 세전이익 (분기 자동배분 / 연간 입력) | B25: =ROUND(B21/$J$21*$J$25,1) -> -6.8 | C25: =ROUND(C21/$J$21*$J$25,1) -> 2.1 | D25: =ROUND(D21/$J$21*$J$25,1) -> 26.6 | E25: =$J$25-SUM(B25:D25) -> 31.6 | F25: =ROUND(F21/$K$21*$K$25,1) -> 41.8 | G25: =ROUND(G21/$K$21*$K$25,1) -> 44.7 | H25: =ROUND(H21/$K$21*$K$25,1) -> 50.4 | I25: =$K$25-SUM(F25:H25) -> 50.4 | J25: 53.5 | K25: 187.3 | L25: 228.5
A26: 지배주주순이익 (분기 자동배분 / 연간 입력) | B26: =ROUND(B21/$J$21*$J$26,1) -> -6.2 | C26: =ROUND(C21/$J$21*$J$26,1) -> 1.9 | D26: =ROUND(D21/$J$21*$J$26,1) -> 24.3 | E26: =$J$26-SUM(B26:D26) -> 28.8 | F26: =ROUND(F21/$K$21*$K$26,1) -> 33.5 | G26: =ROUND(G21/$K$21*$K$26,1) -> 35.8 | H26: =ROUND(H21/$K$21*$K$26,1) -> 40.3 | I26: =$K$26-SUM(F26:H26) -> 40.3 | J26: 48.8 | K26: 149.9 | L26: 182.8
A28: 밸류에이션 적용 EPS (원, 2026F) | K28: ='05_도표1_Valuation'!$C$6 -> 3033
A30: ④ 연간 손익 요약 (자동계산 — 위 분기·연간 입력을 합산)
A31: 항목 | B31: 2023 | C31: 2024 | D31: 2025F | E31: 2026F | F31: 2027F | G31: 단위
A32: 매출액 | B32: 909.7 | C32: 892.1 | D32: =J16 -> 1065.3 | E32: =K16 -> 1485.5 | F32: =L16 -> 1633.3 | G32: 십억원
A33: 영업이익 | B33: 23.7 | C33: 11.3 | D33: =J21 -> 49.1 | E33: =K21 -> 180 | F33: =L21 -> 218.3 | G33: 십억원
A34: 세전이익 | B34: 28.4 | C34: 30.2 | D34: =J25 -> 53.5 | E34: =K25 -> 187.3 | F34: =L25 -> 228.5 | G34: 십억원
A35: 지배주주순이익 | B35: 25.4 | C35: 23.8 | D35: =J26 -> 48.8 | E35: =K26 -> 149.9 | F35: =L26 -> 182.8 | G35: 십억원
A36: EPS | B36: =B35*1000000/$B$7 -> 513.9942 | C36: =C35*1000000/$B$7 -> 481.61661 | D36: =D35*1000000/$B$7 -> 987.51642 | E36: =E35*1000000/$B$7 -> 3033.3752 | F36: =F35*1000000/$B$7 -> 3699.1394 | G36: 원
A38: ⑤ 원문(도표 6) 대비 확인
A39: 체크 항목 | B39: 2025F | C39: 2026F | D39: 비고
A40: 분기 합계 매출 vs 도표6 연간 | B40: =J16-'10_도표6_분기실적전망_수정후'!K5 -> 0 | C40: =K16-'10_도표6_분기실적전망_수정후'!L5 -> -0.1 | D40: 0에 가까울수록 도표6과 일치
A41: EPS(2026F) vs 도표1 적용 EPS | C41: =E36-'05_도표1_Valuation'!$C$6 -> 0.37522184 | D41: 대덕전자는 도표1 EPS가 추정재무제표 EPS와 동일합니다 (ISC와 달리 괴리 없음)
A43: 전년 동기 비교 기준 — 2024년 분기 실적 (하나증권 도표6·7 YoY%로 역산, DART 연간실적과 대조)
A44: 매출액 (2024, 역산) | B44: 214.8 | C44: 238.3 | D44: 232.7 | E44: 206.4 | J44: =SUM(B44:E44) -> 892.2
A45: 영업이익 (2024, 역산) | B45: -2.9 | C45: 10.7 | D45: 9.2 | E45: -6 | J45: =SUM(B45:E45) -> 11
A47: 자료: 대덕전자, 하나증권 4Q25 Earnings Review (2026.01.30), DART 정기보고서 | 금액 단위: 십억원, EPS: 원
A48: 주) 세그먼트 매출 구조는 Substrate PKG → Memory/Logic 하위항목 → MLB → Flexible 순서로 표시했습니다. Substrate PKG는 Memory와 Logic의 합계이며, 매출액(계)은 Substrate PKG + MLB + Flexible로 자동 계산됩니다.
A49: 주) 2027F 매출액(세그먼트 분해)·세전이익 228.5·지배주주순이익 182.8(십억원)은 원문 도표 6·7에 없는 확장 추정치입니다. 매출은 세그먼트별 성장률 가정(Memory +14.8%, Logic +8.0%, MLB +2.0%, Flexible 0%)을 적용해 하나증권 밸류에이션 전제인 연간 매출 1,633.3십억원과 정확히 일치하도록 배분했고, 세전이익·순이익은 2026F 대비 증가율 추세를 준용했습니다.
...

Sheet M2_목표주가_타겟멀티플
A1: 목표주가 산출 — Target P/E 모델
A2: Target P/E 목표주가 산출. EPS와 밸류에이션 방식은 드롭다운 선택.
A4: ① 입력값 — 노랑: 애널리스트 추정 입력 / 연청회색: 공시·시장 자동 수집
A5: 구분 | B5: 항목 | C5: 입력값 | D5: 단위 | E5: 비고 (원문 기준)
A6: 선택 | B6: 적용 EPS 스위치 | C6: 보고서 원문 EPS | D6: 선택 | E6: 드롭다운: M1 자체 계산 EPS 또는 도표1 원문 EPS. 기본값은 보고서 원문 EPS
A7: 산출 | B7: 적정 P/E (선택 방식) | C7: =IF($C$30="Peer 평균 P/E",$C$41,IF($C$30="보고서 원문 P/E",$C$32,$C$31)) -> 26.58 | D7: 배 | E7: 아래 밸류에이션 방식 드롭다운에 따라 자동 선택
A8: 자동 | B8: 현재주가 | C8: 52500 | D8: 원 | E8: 2026.01.29 종가 — 시장 데이터에서 자동 수집
A9: 입력 | B9: 목표주가 반올림 단위 | C9: 1000 | D9: 원 | E9: 제시 목표주가 라운딩 단위 (81,000원 = 1천원 단위 반올림)
A10: 산출 | B10: 적용 EPS (2026F) | C10: =IF($C$6="M1 모델 EPS",M1_실적추정_모델!E36,'05_도표1_Valuation'!$C$6) -> 3033 | D10: 원 | E10: 스위치에 따라 M1 모델값 또는 도표1 원문값 3,033원 선택
A12: ② 산출 (Output)
A13: 구분 | B13: 항목 | C13: 산출값 | D13: 단위 | E13: 산식
A14: 산출 | B14: 목표주가 (산출) | C14: =$C$10*$C$7 -> 80617.14 | D14: 원 | E14: 적용 EPS × 적정 P/E
A15: 산출 | B15: 목표주가 (제시) | C15: =ROUND($C$14/$C$9,0)*$C$9 -> 81000 | D15: 원 | E15: 산출 목표주가를 반올림 단위로 라운딩
A16: 산출 | B16: 상승여력 | C16: =$C$15/$C$8-1 -> 0.54285714 | D16: % | E16: 목표주가(제시) ÷ 현재주가 − 1
A17: 산출 | B17: 현재주가 내재 P/E | C17: =$C$8/$C$10 -> 17.309594 | D17: 배 | E17: 현재주가 ÷ 적용 EPS
A19: ③ 원문 대조 및 EPS 기준 비교 (정합성 체크)
A20: 구분 | B20: 항목 | C20: 값 | D20: 원문값 | E20: 비고
A21: 체크 | B21: 목표주가 (모델, 제시) | C21: =$C$15 -> 81000 | D21: 81000 | E21: 원문 도표1 목표주가
A22: 체크 | B22: 상승여력 (모델) | C22: =$C$16 -> 0.54285714 | D22: 0.543 | E22: 원문 도표1 상승여력
A23: 비교 | B23: 컨센서스 2026 EPS | C23: ='02_p1_Consensus'!$C$8 -> 2579 | E23: 컨센서스는 하나증권보다 2026F EPS를 낮게(2,579원) 봅니다 — 도표1 3,033원 대비 -15%
A24: 비교 | B24: 적용 EPS vs 컨센서스 차이 | C24: =$C$10/C23-1 -> 0.17603722 | E24: 하나증권 목표주가가 컨센서스보다 낙관적인 26F EPS를 전제로 함을 보여줍니다
A26: 자료: 대덕전자, 하나증권
A27: 주) 목표주가 산출값(≈80,600원)을 1천원 단위로 반올림하면 원문 제시 목표주가 81,000원이 재현됩니다. 상승여력은 제시 목표주가 기준 54.3%로 원문과 일치합니다.
A28: ④ 밸류에이션 방식 및 Peer P/E (4Q25 리뷰 시점)
A29: 구분 | B29: 항목 | C29: 값 | D29: 단위 | E29: 비고
A30: 선택 | B30: 밸류에이션 방식 | C30: Peer 평균 P/E | D30: 선택 | E30: Peer 평균 / 보고서 원문 / 직접 입력
A31: 입력 | B31: 직접 입력 P/E | C31: 26.58 | D31: 배 | E31: 직접 입력 방식을 선택할 때 적용
A32: 원문 | B32: 보고서 원문 P/E | C32: 26.58 | D32: 배 | E32: 하나증권 4Q25 도표1의 Target P/E
A34: 구분 | B34: Peer 회사 | C34: 2026E P/E | D34: 단위 | E34: 기준 / 상태
A35: Peer | B35: Ibiden | C35: 36 | D35: 배 | E35: 4Q25 시점 근사·보고서 평균 역산 구성
A36: Peer | B36: Unimicron | C36: 32 | D36: 배 | E36: 4Q25 시점 근사·보고서 평균 역산 구성
A37: Peer | B37: 삼성전기 | C37: 22.8 | D37: 배 | E37: 4Q25 시점 근사·보고서 평균 역산 구성
A38: Peer | B38: 심텍 | C38: 27.1 | D38: 배 | E38: 4Q25 시점 근사·보고서 평균 역산 구성
A39: Peer | B39: 해성디에스 | C39: 15 | D39: 배 | E39: 4Q25 시점 근사·보고서 평균 역산 구성
A40: 추가 | B40: 코리아써키트 | D40: 배 | E40: 1Q26 보고서에서 추가된 Peer — 시연 시 값 입력
A41: 산출 | B41: Peer 평균 P/E | C41: =SUM($C$35:$C$40)/COUNT($C$35:$C$40) -> 26.58 | D41: 배 | E41: 빈 셀은 평균 계산에서 제외
A42: 체크 | B42: Peer 평균 - 보고서 P/E | C42: =$C$41-$C$32 -> 0 | D42: 배 | E42: 코리아써키트 입력 전 0.00배가 되어야 함

Sheet M3_민감도분석
A1: Target P/E × 2026F EPS 목표주가 민감도 (원문에 없는 파생 분석)
A2: M2_목표주가_타겟멀티플 시트의 기준선(적정 P/E 26.58배, EPS 3,033원)을 중심으로 ±2배수/±10% 구간의 목표주가를 계산합니다.
A4: 목표주가 민감도표 (원)
A6: EPS \ P/E | B6: =M2_목표주가_타겟멀티플!$C$7+-2 -> 24.58 | C6: =M2_목표주가_타겟멀티플!$C$7+-1 -> 25.58 | D6: =M2_목표주가_타겟멀티플!$C$7+0 -> 26.58 | E6: =M2_목표주가_타겟멀티플!$C$7+1 -> 27.58 | F6: =M2_목표주가_타겟멀티플!$C$7+2 -> 28.58
A7: =M2_목표주가_타겟멀티플!$C$10*(1+-0.1) -> 2729.7 | B7: =$A7*B$6 -> 67096.026 | C7: =$A7*C$6 -> 69825.726 | D7: =$A7*D$6 -> 72555.426 | E7: =$A7*E$6 -> 75285.126 | F7: =$A7*F$6 -> 78014.826
A8: =M2_목표주가_타겟멀티플!$C$10*(1+-0.05) -> 2881.35 | B8: =$A8*B$6 -> 70823.583 | C8: =$A8*C$6 -> 73704.933 | D8: =$A8*D$6 -> 76586.283 | E8: =$A8*E$6 -> 79467.633 | F8: =$A8*F$6 -> 82348.983
A9: =M2_목표주가_타겟멀티플!$C$10*(1+0) -> 3033 | B9: =$A9*B$6 -> 74551.14 | C9: =$A9*C$6 -> 77584.14 | D9: =M2_목표주가_타겟멀티플!$C$10*M2_목표주가_타겟멀티플!$C$7 -> 80617.14 | E9: =$A9*E$6 -> 83650.14 | F9: =$A9*F$6 -> 86683.14
A10: =M2_목표주가_타겟멀티플!$C$10*(1+0.05) -> 3184.65 | B10: =$A10*B$6 -> 78278.697 | C10: =$A10*C$6 -> 81463.347 | D10: =$A10*D$6 -> 84647.997 | E10: =$A10*E$6 -> 87832.647 | F10: =$A10*F$6 -> 91017.297
A11: =M2_목표주가_타겟멀티플!$C$10*(1+0.1) -> 3336.3 | B11: =$A11*B$6 -> 82006.254 | C11: =$A11*C$6 -> 85342.554 | D11: =$A11*D$6 -> 88678.854 | E11: =$A11*E$6 -> 92015.154 | F11: =$A11*F$6 -> 95351.454
A13: 주) 이 시트에는 사용자가 직접 입력하는 셀이 없습니다. M2의 적용 EPS·적정 P/E를 변경하면 민감도 행·열과 기준값(D9)이 모두 자동으로 갱신됩니다.

Sheet 01_p1_투자의견
A1: 대덕전자 (353200) — 투자의견
A2: 하나증권 리포트 p.1 게재
A4: 투자의견
A5: 항목 | B5: 값 | C5: 비고
A6: 투자의견 | B6: BUY (유지) | C6: 변동 없음
A7: 목표주가(12M) | B7: 81000 | C7: 상향 (기존 59,000원)
A8: 현재주가(2026.01.29) | B8: 52500
A10: 자료: 하나증권, 2026.01.29 기준
A11: 주) 목표주가 81,000원과 현재주가 52,500원은 리포트 표지 원문 전사값입니다.

Sheet 01A_p1_KeyData
A1: 대덕전자 (353200) — Key Data
A2: 하나증권 리포트 p.1 게재
A4: Key Data
A5: 항목 | B5: 값 | C5: 단위
A6: KOSPI지수 | B6: 5221.25 | C6: pt
A7: 52주 최고 | B7: 54500 | C7: 원
A8: 52주 최저 | B8: 13120 | C8: 원
A9: 시가총액 | B9: 2594.4 | C9: 십억원
A10: 시가총액비중 | B10: 0.0006 | C10: %
A11: 발행주식수 | B11: 49416.9 | C11: 천주
A12: 60일 평균 거래량 | B12: 1560.2 | C12: 천주
A13: 60일 평균 거래대금 | B13: 74.2 | C13: 십억원
A14: 외국인지분율 | B14: 0.1801 | C14: %
A16: 주요주주 지분율
A17: 주주 | B17: 지분율 | C17: 비고
A18: 대덕 외 5인 | B18: 0.3276
A19: 국민연금공단 | B19: 0.1203
A21: 자료: 하나증권, 2026.01.29 기준
A22: 주) 시가총액비중은 원문 0.06%를 소수값 0.0006으로 저장했습니다.

Sheet 02_p1_Consensus
A1: Consensus Data
A2: 하나증권 리포트 p.1 게재 / 단위: 십억원, 원
A4: 항목 | B4: 2025 | C4: 2026 | D4: 비고
A5: 매출액(십억원) | B5: 1049.6 | C5: 1353.9
A6: 영업이익(십억원) | B6: 47 | C6: 155.9
A7: 순이익(십억원) | B7: 45.6 | C7: 133.9
A8: EPS(원) | B8: 887 | C8: 2579
A9: BPS(원) | B9: 17520 | C9: 19891
A11: 자료: 하나증권 (FnGuide 컨센서스 인용)
A12: 하나증권 추정치 대비 괴리 (파생)
A13: 항목 | B13: 2025 | C13: 2026 | D13: 비고
A14: 매출액 괴리 (하나증권/컨센서스-1) | B14: ='12_p4_손익계산서'!D5/B5-1 -> 0.014958079 | C14: ='12_p4_손익계산서'!E5/C5-1 -> 0.09720068
A15: EPS 괴리 (하나증권/컨센서스-1) | B15: ='14_p4_투자지표'!D6/B8-1 -> 0.067643743 | C15: ='14_p4_투자지표'!E6/C8-1 -> 0.17603722

Sheet 03_p1_주가추이
A1: Stock Price — 표지 차트 대체
A2: 원문은 「대덕전자(좌) vs 상대지수(우)」 월별 주가 차트입니다. 시세 제공 사이트가 대부분 자동 수집을 차단해 전체 월별 시계열은 확보하지 못했고, 리포트에 인쇄된 확정 수치만 아래에 옮겼습니다.
A4: 확보한 지표
A5: 항목 | B5: 값 | C5: 비고
A6: 현재주가 | B6: ='01_p1_투자의견'!B8 -> 52500 | C6: 2026.01.29 종가
A7: 52주 최고 | B7: ='01A_p1_KeyData'!B7 -> 54500
A8: 52주 최저 | B8: ='01A_p1_KeyData'!B8 -> 13120
A9: 시가총액(십억원) | B9: ='01A_p1_KeyData'!B9 -> 2594.4 | C9: 현재주가 × 발행주식수와 유사(단수차이 있음)
A11: 월별 주가·상대지수 시계열 (21.1~26.1)
A12: 미확보 사유: finance.naver.com, stockanalysis.com 등 시세 제공 사이트가 자동 수집을 차단했습니다. 16_p5_투자의견변동_괴리율 시트에 목표주가 변동 이력(날짜별)은 정확히 옮겨져 있어 참고할 수 있습니다.

Sheet 04_p1_FinancialData
A1: Financial Data (요약 투자지표)
A2: 하나증권 리포트 p.1 게재 / 단위: 십억원, %, 배, 원
A4: 투자지표 | B4: 2023 | C4: 2024 | D4: 2025F | E4: 2026F | F4: 단위
A5: 매출액 | B5: 909.7 | C5: 892.1 | D5: 1065.3 | E5: 1485.6 | F5: 십억원
A6: 영업이익 | B6: 23.7 | C6: 11.3 | D6: 49.2 | E6: 180 | F6: 십억원
A7: 세전이익 | B7: 28.4 | C7: 30.2 | D7: 53.5 | E7: 187.3 | F7: 십억원
A8: 순이익 | B8: 25.4 | C8: 23.8 | D8: 48.8 | E8: 149.9 | F8: 십억원
A9: EPS | B9: 493 | C9: 461 | D9: 947 | E9: 3033 | F9: 원
A10: 증감율 | B10: -0.8619 | C10: -0.0649 | D10: 1.0542 | E10: 2.2027 | F10: %
A11: PER | B11: 54.87 | C11: 33.62 | D11: 49.74 | E11: 17.31 | F11: 배
A12: PBR | B12: 1.6 | C12: 0.91 | D12: 2.69 | E12: 2.62 | F12: 배
A13: EV/EBITDA | B13: 8.47 | C13: 4.49 | D13: 13.96 | E13: 8.16 | F13: 배
A14: ROE | B14: 0.0295 | C14: 0.0273 | D14: 0.0549 | E14: 0.1551 | F14: %
A15: BPS | B15: 16857 | C15: 16996 | D15: 17505 | E15: 20014 | F15: 원
A16: DPS | B16: 300 | C16: 400 | D16: 400 | E16: 400 | F16: 원
A18: 정합성 체크 (원문 수치를 수식으로 재계산)
A19: 체크 항목 | B19: 2023 | C19: 2024 | D19: 2025F | E19: 2026F | F19: 비고
A20: 영업이익률 = 영업이익/매출액 | B20: =B6/B5 -> 0.026052545 | C20: =C6/C5 -> 0.012666741 | D20: =D6/D5 -> 0.046184173 | E20: =E6/E5 -> 0.12116317 | F20: 14_p4_투자지표 영업이익률과 대조
A21: PER 재계산 = 주가/EPS | B21: =B11*B9 -> 27050.91 | C21: =C11*C9 -> 15498.82 | D21: =D11*D9 -> 47103.78 | E21: =E11*E9 -> 52501.23 | F21: PER × EPS = 해당 연도 기준주가(원)
A22: 자료: 하나증권
A23: 주) 이 표는 4페이지 추정재무제표(12_p4_손익계산서·14_p4_투자지표)와 완전히 동일한 수치입니다. 표지 요약과 상세 재무제표가 일치함을 확인했습니다.

Sheet 05_도표1_Valuation
A1: 도표 1. 대덕전자 Valuation — 수식 연동 모델
A2: M2 시트의 밸류에이션 방식 드롭다운과 Peer P/E 입력을 바꾸면 목표주가·상승여력과 M3 민감도분석이 자동으로 다시 계산됩니다.
A4: ① 입력값
A5: 구분 | B5: 항목 | C5: 입력값 | D5: 단위 | E5: 비고 (원문 기준)
A6: 입력 | B6: EPS | C6: 3033 | D6: 원 | E6: 26년 EPS — 하나증권 추정재무제표(도표6) 2026F EPS와 동일
A7: 연결 | B7: 적정 P/E | C7: =M2_목표주가_타겟멀티플!$C$7 -> 26.58 | D7: 배 | E7: M2 밸류에이션 방식 드롭다운에서 선택
A8: 자동 | B8: 현재주가 | C8: ='01_p1_투자의견'!B8 -> 52500 | D8: 원 | E8: 2026.01.29 종가 — 시장 데이터에서 자동 수집
A10: ② 산출 (Output)
A11: 구분 | B11: 항목 | C11: 산출값 | D11: 단위 | E11: 산식
A12: 산출 | B12: 목표주가 (산출) | C12: =$C$6*$C$7 -> 80617.14 | D12: 원 | E12: EPS × 적정 P/E
A13: 산출 | B13: 목표주가 (제시) | C13: =ROUND($C$12/1000,0)*1000 -> 81000 | D13: 원 | E13: 1천원 단위로 반올림
A14: 산출 | B14: 상승여력 | C14: =$C$13/$C$8-1 -> 0.54285714 | D14: % | E14: 목표주가(제시) ÷ 현재주가 − 1
A16: ③ 원문 대조 (정합성 체크)
A17: 구분 | B17: 항목 | C17: 값 | D17: 원문값 | E17: 비고
A18: 체크 | B18: 목표주가 (모델) | C18: =$C$13 -> 81000 | D18: 81000
A19: 체크 | B19: 상승여력 (모델) | C19: =$C$14 -> 0.54285714 | D19: 0.543
A21: 자료: 대덕전자, 하나증권
A22: 주) 목표주가 산출값(≈80,617원)을 1천원 단위로 반올림해 원문 제시 목표주가 81,000원이 재현됩니다. 상승여력 54.3%도 원문과 일치합니다.

Sheet 06_도표2_PER_Band
A1: 도표 2. 대덕전자 12MF P/E Band
A2: 원문은 차트여서 주가 시계열이 인쇄되어 있지 않습니다. 인쇄된 밴드 배수만 옮겼습니다.
A4: 밴드 | B4: 배수 (배) | E4: 비고
A5: Band 1 (상단) | B5: 30 | E5: 원문 차트에 표기된 밴드 배수
A6: Band 2 | B6: 25 | E6: 원문 차트에 표기된 밴드 배수
A7: Band 3 (중단) | B7: 20 | E7: 원문 차트에 표기된 밴드 배수
A8: Band 4 | B8: 15 | E8: 원문 차트에 표기된 밴드 배수
A9: Band 5 (하단) | B9: 10 | E9: 원문 차트에 표기된 밴드 배수
A11: 자료: 대덕전자, 하나증권
A13: 정합성 체크 (밴드 배수 기준 내재주가 — 원문에 없는 파생 계산)
A14: 밴드 | B14: 배수 (배) | C14: 내재주가 (원) | D14: 현재주가 대비 | E14: 비고
A15: Band 1 (상단) | B15: =$B$5 -> 30 | C15: =$B15*'14_p4_투자지표'!$E$6 -> 90990 | D15: =$C15/'05_도표1_Valuation'!$C$8-1 -> 0.73314286 | E15: 2026F EPS 3,033원 적용 (참고용)
A16: Band 2 | B16: =$B$6 -> 25 | C16: =$B16*'14_p4_투자지표'!$E$6 -> 75825 | D16: =$C16/'05_도표1_Valuation'!$C$8-1 -> 0.44428571 | E16: 2026F EPS 3,033원 적용 (참고용)
A17: Band 3 (중단) | B17: =$B$7 -> 20 | C17: =$B17*'14_p4_투자지표'!$E$6 -> 60660 | D17: =$C17/'05_도표1_Valuation'!$C$8-1 -> 0.15542857 | E17: 2026F EPS 3,033원 적용 (참고용)
A18: Band 4 | B18: =$B$8 -> 15 | C18: =$B18*'14_p4_투자지표'!$E$6 -> 45495 | D18: =$C18/'05_도표1_Valuation'!$C$8-1 -> -0.13342857 | E18: 2026F EPS 3,033원 적용 (참고용)
A19: Band 5 (하단) | B19: =$B$9 -> 10 | C19: =$B19*'14_p4_투자지표'!$E$6 -> 30330 | D19: =$C19/'05_도표1_Valuation'!$C$8-1 -> -0.42228571 | E19: 2026F EPS 3,033원 적용 (참고용)
A21: 주) 원문 차트는 21.1~26.1 구간의 수정주가와 5개 밴드선을 그린 그래프입니다. 주가 시계열에 데이터 라벨이 없어 눈금으로 추정하면 오차가 커지므로 옮기지 않았고, 인쇄된 밴드 배수만 위 표에 실었습니다.

Sheet 07_도표3_PBR_Band
A1: 도표 3. 대덕전자 12MF P/B Band
A2: 원문은 차트여서 주가 시계열이 인쇄되어 있지 않습니다. 인쇄된 밴드 배수만 옮겼습니다.
A4: 밴드 | B4: 배수 (배) | E4: 비고
A5: Band 1 (상단) | B5: 2.6 | E5: 원문 차트에 표기된 밴드 배수
A6: Band 2 | B6: 2.1 | E6: 원문 차트에 표기된 밴드 배수
A7: Band 3 (중단) | B7: 1.7 | E7: 원문 차트에 표기된 밴드 배수
A8: Band 4 | B8: 1.2 | E8: 원문 차트에 표기된 밴드 배수
A9: Band 5 (하단) | B9: 0.8 | E9: 원문 차트에 표기된 밴드 배수
A11: 자료: 대덕전자, 하나증권
A13: 정합성 체크 (밴드 배수 기준 내재주가 — 원문에 없는 파생 계산)
A14: 밴드 | B14: 배수 (배) | C14: 내재주가 (원) | D14: 현재주가 대비 | E14: 비고
A15: Band 1 (상단) | B15: =$B$5 -> 2.6 | C15: =$B15*'14_p4_투자지표'!$E$7 -> 52036.4 | D15: =$C15/'05_도표1_Valuation'!$C$8-1 -> -0.0088304762 | E15: 2026F BPS 20,014원 적용 (참고용)
A16: Band 2 | B16: =$B$6 -> 2.1 | C16: =$B16*'14_p4_투자지표'!$E$7 -> 42029.4 | D16: =$C16/'05_도표1_Valuation'!$C$8-1 -> -0.19944 | E16: 2026F BPS 20,014원 적용 (참고용)
A17: Band 3 (중단) | B17: =$B$7 -> 1.7 | C17: =$B17*'14_p4_투자지표'!$E$7 -> 34023.8 | D17: =$C17/'05_도표1_Valuation'!$C$8-1 -> -0.35192762 | E17: 2026F BPS 20,014원 적용 (참고용)
A18: Band 4 | B18: =$B$8 -> 1.2 | C18: =$B18*'14_p4_투자지표'!$E$7 -> 24016.8 | D18: =$C18/'05_도표1_Valuation'!$C$8-1 -> -0.54253714 | E18: 2026F BPS 20,014원 적용 (참고용)
A19: Band 5 (하단) | B19: =$B$9 -> 0.8 | C19: =$B19*'14_p4_투자지표'!$E$7 -> 16011.2 | D19: =$C19/'05_도표1_Valuation'!$C$8-1 -> -0.69502476 | E19: 2026F BPS 20,014원 적용 (참고용)
A21: 주) 원문 차트는 21.1~26.1 구간의 수정주가와 5개 밴드선을 그린 그래프입니다. 주가 시계열에 데이터 라벨이 없어 눈금으로 추정하면 오차가 커지므로 옮기지 않았고, 인쇄된 밴드 배수만 위 표에 실었습니다.

Sheet 08_도표4_분기실적추이
A1: 도표 4. 대덕전자 분기별 실적 추이 (매출·OPM)
A2: 단위: 십억원, % / 원문은 차트만 있고 표가 없습니다. 신뢰도에 따라 글씨색을 구분했습니다: 파랑=원문표 그대로(1Q25~4Q26F), 검정=YoY%로 역산(2024), 주황 기울임=차트 이미지 눈금 판독(2021~2023).
A4: 구분 | B4: 1Q21 | C4: 2Q21 | D4: 3Q21 | E4: 4Q21 | F4: 1Q22 | G4: 2Q22 | H4: 3Q22 | I4: 4Q22 | J4: 1Q23 | K4: 2Q23 | L4: 3Q23 | M4: 4Q23 | N4: 1Q24 | O4: 2Q24 | P4: 3Q24 | Q4: 4Q24 | R4: 1Q25 | S4: 2Q25 | T4: 3Q25 | U4: 4Q25 | V4: 1Q26 | W4: 2Q26 | X4: 3Q26 | Y4: 4Q26
A5: 매출액 | B5: 235 | C5: 230 | D5: 256 | E5: 283 | F5: 296 | G5: 343 | H5: 373 | I5: 296 | J5: 218 | K5: 220 | L5: 238 | M5: 235 | N5: 214.8 | O5: 238.3 | P5: 232.7 | Q5: 206.4 | R5: 215.4 | S5: 245.9 | T5: 286.2 | U5: 317.9 | V5: 330 | W5: 354 | X5: 397.7 | Y5: 403.9
A6: 영업이익 | B6: 5.9 | C6: 8.1 | D6: 23 | E6: 25.5 | F6: 42.9 | G6: 61.7 | H6: 78.3 | I6: 48.8 | J6: 9.8 | K6: 6.6 | L6: 2.4 | M6: 8.2 | N6: -2.9 | O6: 10.7 | P6: 9.2 | Q6: -6 | R6: -6.2 | S6: 1.9 | T6: 24.4 | U6: 29 | V6: 40.2 | W6: 43 | X6: 48.4 | Y6: 48.4
A7: OPM | B7: =B6/B5 -> 0.025106383 | C7: =C6/C5 -> 0.035217391 | D7: =D6/D5 -> 0.08984375 | E7: =E6/E5 -> 0.090106007 | F7: =F6/F5 -> 0.14493243 | G7: =G6/G5 -> 0.17988338 | H7: =H6/H5 -> 0.20991957 | I7: =I6/I5 -> 0.16486486 | ... Y7: =Y6/Y5 -> 0.11983164
A9: 자료: 대덕전자, 하나증권 (2021~2023은 도표4 차트 이미지 판독 근사치)

Sheet 09_도표5_수주잔고추이
A1: 도표 5. 대덕전자 분기별 수주잔고 추이
A2: 단위: 억원 / 원문은 차트만 있고 표가 없습니다. 수주잔고는 DART 공시(재무제표 XBRL)에 구조화 항목으로 없어, 도표5 차트 이미지의 눈금을 읽어 근사한 값입니다 (주황 기울임 글씨).
A4: 구분 | B4: 1Q21 | C4: 2Q21 | D4: 3Q21 | E4: 4Q21 | F4: 1Q22 | G4: 2Q22 | H4: 3Q22 | I4: 4Q22 | J4: 1Q23 | K4: 2Q23 | L4: 3Q23 | M4: 4Q23 | N4: 1Q24 | O4: 2Q24 | P4: 3Q24 | Q4: 4Q24 | R4: 1Q25 | S4: 2Q25 | T4: 3Q25
A5: 수주잔고 | B5: 640 | C5: 1300 | D5: 2070 | E5: 1310 | F5: 780 | G5: 1100 | H5: 610 | I5: 330 | J5: 800 | K5: 380 | L5: 1010 | M5: 340 | N5: 730 | O5: 690 | P5: 780 | Q5: 360 | R5: 800 | S5: 1290 | T5: 3080
A7: 자료: 대덕전자, 하나증권 (차트 이미지 판독 근사치, 억원)
A8: 주) 수주잔고는 IFRS 표준 공시 항목이 아니며 대덕전자·하나증권이 제공한 수치로, DART XBRL(사업보고서·분기보고서)에서 구조화된 형태로 확인되지 않았습니다. 임의 추정이 아니라 원문 차트의 눈금을 읽은 근사치임을 밝혀둡니다 (마지막 분기 3Q25 ≈3,080억원으로 최대치를 기록).

Sheet 10_도표6_분기실적전망_수정후
A1: 도표 6. 대덕전자 분기별 실적 전망(수정 후)
A2: 단위: 십억원, % / 음영 = 전망치(F) 및 연간 열
A4: 구분 | B4: 1Q25 | C4: 2Q25 | D4: 3Q25 | E4: 4Q25 | F4: 1Q26F | G4: 2Q26F | H4: 3Q26F | I4: 4Q26F | J4: 2024 | K4: 2025F | L4: 2026F | M4: 단위
A5: 매출액 | B5: 215.4 | C5: 245.9 | D5: 286.2 | E5: 317.9 | F5: 330 | G5: 354 | H5: 397.7 | I5: 403.9 | J5: 892.1 | K5: 1065.3 | L5: 1485.6 | M5: 십억원
A6: YoY | B6: 0.003 | C6: 0.032 | D6: 0.23 | E6: 0.54 | F6: 0.532 | G6: 0.44 | H6: 0.39 | I6: 0.27 | J6: -0.019 | K6: 0.194 | L6: 0.395 | M6: %
A7: QoQ | B7: 0.043 | C7: 0.142 | D7: 0.164 | E7: 0.111 | F7: 0.038 | G7: 0.073 | H7: 0.123 | I7: 0.015 | M7: %
A8: Substrate PKG | B8: 176.6 | C8: 207.8 | D8: 243.8 | E8: 273.7 | F8: 283.9 | G8: 296.9 | H8: 311.7 | I8: 308.7 | J8: 768.8 | K8: 901.9 | L8: 1201.2 | M8: 십억원
A9: -Memory | B9: 101.3 | C9: 127.1 | D9: 158 | E9: 160.5 | F9: 162.1 | G9: 168.3 | H9: 174.6 | I9: 168.7 | J9: 476.5 | K9: 546.9 | L9: 673.7 | M9: 십억원
A10: -Logic | B10: 75.3 | C10: 80.7 | D10: 85.8 | E10: 113.2 | F10: 121.8 | G10: 128.6 | H10: 137 | I10: 140.1 | J10: 292.4 | K10: 355 | L10: 527.5 | M10: 십억원
A11: MLB | B11: 38.8 | C11: 37.7 | D11: 42.4 | E11: 44.2 | F11: 46.1 | G11: 57.1 | H11: 86 | I11: 95.1 | J11: 122.6 | K11: 163.1 | L11: 284.4 | M11: 십억원
A12: Flexible | B12: 0 | C12: 0.3 | D12: 0 | E12: 0 | F12: 0 | G12: 0 | H12: 0 | I12: 0 | J12: 0.8 | K12: 0.3 | L12: 0 | M12: 십억원
A13: 매출비중
A14: Substrate PKG(%) | B14: 0.82 | C14: 0.845 | D14: 0.852 | E14: 0.861 | F14: 0.86 | G14: 0.839 | H14: 0.784 | I14: 0.764 | J14: 0.862 | K14: 0.847 | L14: 0.809 | M14: %
A15: -Memory(%) | B15: 0.47 | C15: 0.517 | D15: 0.552 | E15: 0.505 | F15: 0.491 | G15: 0.475 | H15: 0.439 | I15: 0.418 | J15: 0.534 | K15: 0.513 | L15: 0.453 | M15: %
A16: -Logic(%) | B16: 0.35 | C16: 0.328 | D16: 0.3 | E16: 0.356 | F16: 0.369 | G16: 0.363 | H16: 0.345 | I16: 0.347 | J16: 0.328 | K16: 0.333 | L16: 0.355 | M16: %
A17: MLB(%) | B17: 0.18 | C17: 0.153 | D17: 0.148 | E17: 0.139 | F17: 0.14 | G17: 0.161 | H17: 0.216 | I17: 0.236 | J17: 0.137 | K17: 0.153 | L17: 0.191 | M17: %
A18: Flexible(%) | B18: 0 | C18: 0.001 | D18: 0 | E18: 0 | F18: 0 | G18: 0 | H18: 0 | I18: 0 | J18: 0.001 | K18: 0 | L18: 0 | M18: %
A19: OP | B19: -6.2 | C19: 1.9 | D19: 24.4 | E19: 29 | F19: 40.2 | G19: 43 | H19: 48.4 | I19: 48.4 | J19: 11.3 | K19: 49.2 | L19: 180 | M19: 십억원
A20: YoY | B20: 1.15 | C20: -0.822 | D20: 1.655 | E20: -5.864 | F20: -7.482 | G20: 22.01 | H20: 0.978 | I20: 0.668 | J20: -0.526 | K20: 3.366 | L20: 2.662 | M20: %
A21: QoQ | B21: 0.041 | C21: -1.314 | D21: 12.074 | E21: 0.188 | F21: 0.384 | G21: 0.071 | H21: 0.124 | I21: 0.001 | M21: %
A22: OPM | B22: -0.029 | C22: 0.008 | D22: 0.085 | E22: 0.091 | F22: 0.122 | G22: 0.122 | H22: 0.122 | I22: 0.12 | J22: 0.013 | K22: 0.046 | L22: 0.121 | M22: %
A24: 자료: 대덕전자, 하나증권
A26: 정합성 체크 (원문 수치를 수식으로 재계산)
A27: 체크 항목 | B27: 1Q25 | C27: 2Q25 | D27: 3Q25 | E27: 4Q25 | F27: 1Q26F | G27: 2Q26F | H27: 3Q26F | I27: 4Q26F | J27: 2024 | K27: 2025F | L27: 2026F | M27: 단위
A28: 세그먼트 합계 (Substrate+MLB+Flex) | B28: =B8+B11+B12 -> 215.4 | C28: =C8+C11+C12 -> 245.8 | D28: =D8+D11+D12 -> 286.2 | E28: =E8+E11+E12 -> 317.9 | F28: =F8+F11+F12 -> 330 | G28: =G8+G11+G12 -> 354 | H28: =H8+H11+H12 -> 397.7 | I28: =I8+I11+I12 -> 403.8 | ... L28: =L8+L11+L12 -> 1485.6
A29: vs 원문 매출액 (차이) | B29: =B28-B5 -> 0 | C29: =C28-C5 -> -0.1 | D29: =D28-D5 -> 0 | E29: =E28-E5 -> 0 | F29: =F28-F5 -> 0 | G29: =G28-G5 -> 0 | H29: =H28-H5 -> 0 | I29: =I28-I5 -> -0.1 | ... L29: =L28-L5 -> 0
A30: OPM 재계산 (OP/매출액) | B30: =IFERROR(B19/B5,"") -> -0.028783658 | C30: =IFERROR(C19/C5,"") -> 0.0077267182 | D30: =IFERROR(D19/D5,"") -> 0.085255066 | E30: =IFERROR(E19/E5,"") -> 0.091223655 | F30: =IFERROR(F19/F5,"") -> 0.12181818 | G30: =IFERROR(G19/G5,"") -> 0.12146893 | H30: =IFERROR(H19/H5,"") -> 0.12169977 | I30: =IFERROR(I19/I5,"") -> 0.11983164 | ... L30: =IFERROR(L19/L5,"") -> 0.12116317
A32: 주) 원문 연간 수치와 분기 합계 사이의 0.1 내외 차이는 보고서의 소수 첫째자리 반올림 표기에서 발생하는 것으로, 오기입이 아닙니다.

Sheet 11_도표7_분기실적전망_수정전
A1: 도표 7. 대덕전자 분기별 실적 전망(수정 전)
A2: 단위: 십억원, % / 음영 = 전망치(F) 및 연간 열
A4: 구분 | B4: 1Q25 | C4: 2Q25 | D4: 3Q25 | E4: 4Q25F | F4: 1Q26F | G4: 2Q26F | H4: 3Q26F | I4: 4Q26F | J4: 2024 | K4: 2025F | L4: 2026F | M4: 단위
A5: 매출액 | B5: 215.4 | C5: 245.9 | D5: 286.2 | E5: 307.4 | F5: 314.2 | G5: 332.7 | H5: 348.5 | I5: 348.8 | J5: 892.1 | K5: 1054.8 | L5: 1344.2 | M5: 십억원
A6: YoY | B6: 0.003 | C6: 0.032 | D6: 0.23 | E6: 0.489 | F6: 0.459 | G6: 0.353 | H6: 0.218 | I6: 0.135 | J6: -0.019 | K6: 0.182 | L6: 0.274 | M6: %
A7: QoQ | B7: 0.043 | C7: 0.142 | D7: 0.164 | E7: 0.074 | F7: 0.022 | G7: 0.059 | H7: 0.047 | I7: 0.001 | M7: %
A8: Substrate PKG | B8: 176.6 | C8: 207.8 | D8: 243.8 | E8: 263.2 | F8: 269.6 | G8: 283.6 | H8: 289.8 | I8: 283 | J8: 768.8 | K8: 891.5 | L8: 1126 | M8: 십억원
A9: -Memory | B9: 101.3 | C9: 127.1 | D9: 158 | E9: 166.7 | F9: 170 | G9: 179.2 | H9: 182.4 | I9: 175.5 | J9: 476.5 | K9: 553.1 | L9: 707.1 | M9: 십억원
A10: -Logic | B10: 75.3 | C10: 80.7 | D10: 85.8 | E10: 96.5 | F10: 99.7 | G10: 104.4 | H10: 107.4 | I10: 107.4 | J10: 292.4 | K10: 338.3 | L10: 418.9 | M10: 십억원
A11: MLB | B11: 38.8 | C11: 37.7 | D11: 42.4 | E11: 44.2 | F11: 44.6 | G11: 49.1 | H11: 58.7 | I11: 65.8 | J11: 122.6 | K11: 163.1 | L11: 218.2 | M11: 십억원
A12: Flexible | B12: 0 | C12: 0.3 | D12: 0 | E12: 0 | F12: 0 | G12: 0 | H12: 0 | I12: 0 | J12: 0.8 | K12: 0.3 | L12: 0 | M12: 십억원
A13: 매출비중
A14: Substrate PKG(%) | B14: 0.82 | C14: 0.845 | D14: 0.852 | E14: 0.856 | F14: 0.858 | G14: 0.852 | H14: 0.832 | I14: 0.811 | J14: 0.862 | K14: 0.844 | L14: 0.838 | M14: %
A15: -Memory(%) | B15: 0.47 | C15: 0.517 | D15: 0.552 | E15: 0.542 | F15: 0.541 | G15: 0.539 | H15: 0.523 | I15: 0.503 | J15: 0.534 | K15: 0.524 | L15: 0.526 | M15: %
A16: -Logic(%) | B16: 0.35 | C16: 0.328 | D16: 0.3 | E16: 0.314 | F16: 0.317 | G16: 0.314 | H16: 0.308 | I16: 0.308 | J16: 0.328 | K16: 0.321 | L16: 0.312 | M16: %
A17: MLB(%) | B17: 0.18 | C17: 0.153 | D17: 0.148 | E17: 0.144 | F17: 0.142 | G17: 0.148 | H17: 0.168 | I17: 0.189 | J17: 0.137 | K17: 0.155 | L17: 0.162 | M17: %
A18: Flexible(%) | B18: 0 | C18: 0.001 | D18: 0 | E18: 0 | F18: 0 | G18: 0 | H18: 0 | I18: 0 | J18: 0.001 | K18: 0 | L18: 0 | M18: %
A19: OP | B19: -6.2 | C19: 1.9 | D19: 24.4 | E19: 25.8 | F19: 31.1 | G19: 36.9 | H19: 40.5 | I19: 39.4 | J19: 11.3 | K19: 45.9 | L19: 148 | M19: 십억원
A20: YoY | B20: 1.15 | C20: -0.822 | D20: 1.655 | E20: -5.318 | F20: -6.021 | G20: 18.746 | H20: 0.658 | I20: 0.528 | J20: -0.526 | K20: 3.076 | L20: 2.224 | M20: %
A21: QoQ | B21: 0.041 | C21: -1.314 | D21: 12.074 | E21: 0.054 | F21: 0.208 | G21: 0.186 | H21: 0.098 | I21: -0.028 | M21: %
A22: OPM | B22: -0.029 | C22: 0.008 | D22: 0.085 | E22: 0.084 | F22: 0.099 | G22: 0.111 | H22: 0.116 | I22: 0.113 | J22: 0.013 | K22: 0.044 | L22: 0.11 | M22: %
A24: 자료: 대덕전자, 하나증권
A26: 정합성 체크 (원문 수치를 수식으로 재계산)
A27: 체크 항목 | B27: 1Q25 | C27: 2Q25 | D27: 3Q25 | E27: 4Q25F | F27: 1Q26F | G27: 2Q26F | H27: 3Q26F | I27: 4Q26F | J27: 2024 | K27: 2025F | L27: 2026F | M27: 단위
A28: 세그먼트 합계 (Substrate+MLB+Flex) | B28: =B8+B11+B12 -> 215.4 | C28: =C8+C11+C12 -> 245.8 | D28: =D8+D11+D12 -> 286.2 | E28: =E8+E11+E12 -> 307.4 | F28: =F8+F11+F12 -> 314.2 | G28: =G8+G11+G12 -> 332.7 | H28: =H8+H11+H12 -> 348.5 | I28: =I8+I11+I12 -> 348.8 | ... L28: =L8+L11+L12 -> 1344.2
A29: vs 원문 매출액 (차이) | B29: =B28-B5 -> 0 | C29: =C28-C5 -> -0.1 | D29: =D28-D5 -> 0 | E29: =E28-E5 -> 0 | F29: =F28-F5 -> 0 | G29: =G28-G5 -> 0 | H29: =H28-H5 -> 0 | I29: =I28-I5 -> 0 | ... L29: =L28-L5 -> 0
A30: OPM 재계산 (OP/매출액) | B30: =IFERROR(B19/B5,"") -> -0.028783658 | C30: =IFERROR(C19/C5,"") -> 0.0077267182 | D30: =IFERROR(D19/D5,"") -> 0.085255066 | E30: =IFERROR(E19/E5,"") -> 0.083929733 | F30: =IFERROR(F19/F5,"") -> 0.09898154 | G30: =IFERROR(G19/G5,"") -> 0.11091073 | H30: =IFERROR(H19/H5,"") -> 0.11621234 | I30: =IFERROR(I19/I5,"") -> 0.11295872 | ... L30: =IFERROR(L19/L5,"") -> 0.11010266
A32: 주) 원문 연간 수치와 분기 합계 사이의 0.1 내외 차이는 보고서의 소수 첫째자리 반올림 표기에서 발생하는 것으로, 오기입이 아닙니다.

Sheet 12_p4_손익계산서
A1: 추정 재무제표 — 손익계산서
A2: 단위: 십억원 / 음영 = 전망치(F). 2026F·2027F 의 매출액·영업이익·세전이익·지배주주순이익은 M1_실적추정_모델 시트를 반영합니다(초록 글씨).
A4: 구분 | B4: 2023 | C4: 2024 | D4: 2025F | E4: 2026F | F4: 2027F | G4: 비고
A5: 매출액 | B5: 909.7 | C5: 892.1 | D5: =M1_실적추정_모델!J16 -> 1065.3 | E5: =M1_실적추정_모델!K16 -> 1485.5 | F5: =M1_실적추정_모델!L16 -> 1633.3
A6: 매출원가 | B6: 834.5 | C6: 830.6 | D6: 957.2 | E6: 1242.2 | F6: 1355.4
A7: 매출총이익 | B7: =B5-B6 -> 75.2 | C7: =C5-C6 -> 61.5 | D7: =D5-D6 -> 108.1 | E7: =E5-E6 -> 243.3 | F7: =F5-F6 -> 277.9
A8: 판관비 | B8: 51.4 | C8: 50.3 | D8: 59 | E8: 63.3 | F8: 59.5
A9: 영업이익 | B9: 23.7 | C9: 11.3 | D9: =M1_실적추정_모델!J21 -> 49.1 | E9: =M1_실적추정_모델!K21 -> 180 | F9: =M1_실적추정_모델!L21 -> 218.3
A10: 금융손익 | B10: 9.1 | C10: 17.1 | D10: 0.7 | E10: 9.4 | F10: 9.1
A11: 종속/관계기업손익 | B11: 0 | C11: 0 | D11: -1.8 | E11: -2.1 | F11: 5.5
A12: 기타영업외손익 | B12: -4.5 | C12: 1.8 | D12: 5.5 | E12: 0 | F12: -4.5
A13: 세전이익 | B13: 28.4 | C13: 30.2 | D13: =M1_실적추정_모델!J25 -> 53.5 | E13: =M1_실적추정_모델!K25 -> 187.3 | F13: =M1_실적추정_모델!L25 -> 228.5
A14: 법인세 | B14: 3 | C14: 6.4 | D14: 4.7 | E14: 37.5 | F14: 45.7
A15: 계속사업이익 | B15: =B13-B14 -> 25.4 | C15: =C13-C14 -> 23.8 | D15: =D19 -> 48.8 | E15: =E19 -> 149.9 | F15: =F19 -> 182.8
A16: 중단사업이익 | B16: 0 | C16: 0 | D16: 0 | E16: 0 | F16: 0
A17: 당기순이익 | B17: =B15+B16 -> 25.4 | C17: =C15+C16 -> 23.8 | D17: =D15+D16 -> 48.8 | E17: =E15+E16 -> 149.9 | F17: =F15+F16 -> 182.8
A18: 비지배주주지분순이익 | B18: 0 | C18: 0 | D18: 0 | E18: 0 | F18: 0
A19: 지배주주순이익 | B19: 25.4 | C19: 23.8 | D19: =M1_실적추정_모델!J26 -> 48.8 | E19: =M1_실적추정_모델!K26 -> 149.9 | F19: =M1_실적추정_모델!L26 -> 182.8
A20: 지배주주지분포괄이익 | B20: 34 | C20: 22.6 | D20: 46.8 | E20: 149.9 | F20: 182.8
A21: NOPAT | B21: 21.2 | C21: 8.9 | D21: 44.8 | E21: 144 | F21: 174.7
A22: EBITDA | B22: 138.8 | C22: 128.7 | D22: 150.1 | E22: 274.3 | F22: 308.8
A24: 성장성 (%)
A25: 매출액증가율 | B25: -0.3088 | C25: -0.0193 | D25: 0.1941 | E25: 0.3945 | F25: 0.0994
A26: NOPAT증가율 | B26: -0.8788 | C26: -0.5802 | D26: 4.0337 | E26: 2.2143 | F26: 0.2132
A27: EBITDA증가율 | B27: -0.5885 | C27: -0.0728 | D27: 0.1663 | E27: 0.8274 | F27: 0.1258
A28: 영업이익증가율 | B28: -0.8981 | C28: -0.5232 | D28: 3.354 | E28: 2.6585 | F28: 0.2128
A29: (지배주주)순익증가율 | B29: -0.8619 | C29: -0.063 | D29: 1.0504 | E29: 2.0717 | F29: 0.2195
A30: EPS증가율 | B30: -0.8619 | C30: -0.0649 | D30: 1.0542 | E30: 2.2027 | F30: 0.2196
A31: 수익성 (%)
A32: 매출총이익률 | B32: 0.0827 | C32: 0.0689 | D32: 0.1015 | E32: 0.1638 | F32: 0.1701
A33: EBITDA이익률 | B33: 0.1526 | C33: 0.1443 | D33: 0.1409 | E33: 0.1846 | F33: 0.1891
A34: 영업이익률 | B34: 0.0261 | C34: 0.0127 | D34: 0.0462 | E34: 0.1212 | F34: 0.1337
A35: 계속사업이익률 | B35: 0.0279 | C35: 0.0267 | D35: 0.0458 | E35: 0.1009 | F35: 0.1119
A37: 자료: 하나증권
A39: 정합성 체크 (원문 수치를 수식으로 재계산)
A40: 체크 항목 | B40: 2023 | C40: 2024 | D40: 2025F | E40: 2026F | F40: 2027F | G40: 비고
A41: 매출총이익 = 매출액 − 매출원가 | B41: =B5-B6 -> 75.2 | C41: =C5-C6 -> 61.5 | D41: =D5-D6 -> 108.1 | E41: =E5-E6 -> 243.3 | F41: =F5-F6 -> 277.9 | G41: 원문 매출총이익과 대조
A42: 영업이익 = 매출총이익 − 판관비 | B42: =B7-B8 -> 23.8 | C42: =C7-C8 -> 11.2 | D42: =D7-D8 -> 49.1 | E42: =E7-E8 -> 180 | F42: =F7-F8 -> 218.4 | G42: 원문 영업이익과 대조
A43: 영업이익률 재계산 | B43: =B9/B5 -> 0.026052545 | C43: =C9/C5 -> 0.012666741 | D43: =D9/D5 -> 0.046090303 | E43: =E9/E5 -> 0.12117132 | F43: =F9/F5 -> 0.13365579
A44: 유효법인세율 | B44: =B14/B13 -> 0.1056338 | C44: =C14/C13 -> 0.21192053 | D44: =D14/D13 -> 0.087850467 | E44: =E14/E13 -> 0.20021356 | F44: =F14/F13 -> 0.2
...

Sheet 13_p4_대차대조표
A1: 추정 재무제표 — 대차대조표
A2: 단위: 십억원 / 음영 = 전망치(F)
A4: 구분 | B4: 2023 | C4: 2024 | D4: 2025F | E4: 2026F | F4: 2027F | G4: 비고
A5: 유동자산 | B5: 433.1 | C5: 465.9 | D5: 667.7 | E5: 893.2 | F5: 1107.9
A6: 금융자산 | B6: 203.2 | C6: 221.2 | D6: 305.3 | E6: 432.8 | F6: 601.8
A7: 현금성자산 | B7: 76.6 | C7: 38.2 | D7: 23.5 | E7: 74.8 | F7: 208.2
A8: 매출채권 | B8: 123.2 | C8: 128.4 | D8: 197.7 | E8: 251.1 | F8: 276.1
A9: 재고자산 | B9: 90.6 | C9: 100.5 | D9: 140.4 | E9: 178.4 | F9: 196.1
A10: 기타유동자산 | B10: 16.1 | C10: 15.8 | D10: 24.3 | E10: 30.9 | F10: 33.9
A11: 비유동자산 | B11: 694.5 | C11: 622.9 | D11: 582.9 | E11: 567.7 | F11: 546.3
A12: 투자자산 | B12: 7 | C12: 7.3 | D12: 6.8 | E12: 6.9 | F12: 6.9
A13: 금융자산 | B13: 7 | C13: 7.3 | D13: 6.8 | E13: 6.9 | F13: 6.9
A14: 유형자산 | B14: 629.2 | C14: 567.7 | D14: 531.7 | E14: 516.3 | F14: 494.7
A15: 무형자산 | B15: 12.8 | C15: 11 | D15: 10.5 | E15: 10.6 | F15: 10.8
A16: 기타비유동자산 | B16: 45.5 | C16: 36.9 | D16: 33.9 | E16: 33.9 | F16: 33.9
... A34: 순금융부채 | B34: -183 | C34: -205.2 | D34: -262.4 | E34: -389.8 | F34: -565.5
A36: 자료: 하나증권
A38: 정합성 체크 (원문 수치를 수식으로 재계산)
A39: 체크 항목 | B39: 2023 | C39: 2024 | D39: 2025F | E39: 2026F | F39: 2027F | G39: 비고
A40: 자산총계 = 유동자산 + 비유동자산 | B40: =B5+B11 -> 1127.6 | C40: =C5+C11 -> 1088.8 | D40: =D5+D11 -> 1250.6 | E40: =E5+E11 -> 1460.9 | F40: =F5+F11 -> 1654.2
A41: 부채총계 = 유동부채 + 비유동부채 | B41: =B18+B22 -> 259.2 | C41: =C18+C22 -> 213.2 | D41: =D18+D22 -> 348.9 | E41: =E18+E22 -> 429.9 | F41: =F18+F22 -> 461
A42: 자본총계 = 자산총계 − 부채총계 | B42: =B17-B25 -> 868.3 | C42: =C17-C25 -> 875.5 | D42: =D17-D25 -> 901.8 | E42: =E17-E25 -> 1031 | F42: =F17-F25 -> 1193.2
A43: 부채비율 = 부채총계/자본총계 | B43: =B25/B33 -> 0.29851434 | C43: =C25/C33 -> 0.24351799 | D43: =D25/D33 -> 0.38682489 | E43: =E25/E33 -> 0.41697381 | F43: =F25/F33 -> 0.38635602
A45: 주) 원문은 소수 첫째자리까지 반올림 표기되어 있어, 재계산값과 0.1 내외 차이가 날 수 있습니다.

Sheet 14_p4_투자지표
A1: 추정 재무제표 — 투자지표
A2: 단위: 원, 배, %
A4: 주당지표(원)
A5: 구분 | B5: 2023 | C5: 2024 | D5: 2025F | E5: 2026F | F5: 2027F | G5: 비고
A6: EPS | B6: 493 | C6: 461 | D6: 947 | E6: 3033 | F6: 3699
A7: BPS | B7: 16857 | C7: 16996 | D7: 17505 | E7: 20014 | F7: 23163
A8: CFPS | B8: 3645 | C8: 3157 | D8: 3451 | E8: 5283 | F8: 6193
A9: EBITDAPS | B9: 2694 | C9: 2498 | D9: 2914 | E9: 5324 | F9: 5995
A10: SPS | B10: 17659 | C10: 17319 | D10: 20681 | E10: 28840 | F10: 31707
A11: DPS | B11: 300 | C11: 400 | D11: 400 | E11: 400 | F11: 400
A12: 주가지표(배)
A13: 구분 | B13: 2023 | C13: 2024 | D13: 2025F | E13: 2026F | F13: 2027F | G13: 비고
A14: PER | B14: 54.87 | C14: 33.62 | D14: 49.74 | E14: 17.31 | F14: 14.19
A15: PBR | B15: 1.6 | C15: 0.91 | D15: 2.69 | E15: 2.62 | F15: 2.27
A16: PCFR | B16: 7.42 | C16: 4.91 | D16: 13.65 | E16: 9.94 | F16: 8.48
A17: EV/EBITDA | B17: 8.47 | C17: 4.49 | D17: 13.96 | E17: 8.16 | F17: 6.68
A18: PSR | B18: 1.53 | C18: 0.89 | D18: 2.28 | E18: 1.82 | F18: 1.66
A19: 재무비율(%)
A20: 구분 | B20: 2023 | C20: 2024 | D20: 2025F | E20: 2026F | F20: 2027F | G20: 비고
A21: ROE | B21: 0.0295 | C21: 0.0273 | D21: 0.0549 | E21: 0.1551 | F21: 0.1644
A22: ROA | B22: 0.0219 | C22: 0.0214 | D22: 0.0417 | E22: 0.1105 | F22: 0.1174
A23: ROIC | B23: 0.0321 | C23: 0.0138 | D23: 0.0757 | E23: 0.256 | F23: 0.3194
A24: 부채비율 | B24: 0.2985 | C24: 0.2435 | D24: 0.3869 | E24: 0.417 | F24: 0.3863
A25: 순부채비율 | B25: -0.2108 | C25: -0.2344 | D25: -0.291 | E25: -0.3781 | F25: -0.474
A26: 이자보상배율(배) | B26: 25.76 | C26: 16.49 | D26: 39.53 | E26: 134.63 | F26: 0
A28: 자료: 하나증권
A30: 정합성 체크 (원문 수치를 수식으로 재계산)
A31: 체크 항목 | B31: 2023 | C31: 2024 | D31: 2025F | E31: 2026F | F31: 2027F | G31: 비고
A32: PER 재계산 = 현재주가/EPS (2026F) | E32: ='05_도표1_Valuation'!$C$8/E6 -> 17.309594 | F32: 현재주가 52,500원 기준 (전망년도는 원문 표기 그대로)
A33: PBR 재계산 = 현재주가/BPS (2026F) | E33: ='05_도표1_Valuation'!$C$8/E7 -> 2.6231638
A34: ROE 재계산 = EPS/BPS(전기) | C34: =C6/B7 -> 0.027347689 | D34: =D6/C7 -> 0.055718993 | E34: =E6/D7 -> 0.17326478 | F34: =F6/E7 -> 0.18482063
A36: 주) PER·PBR 원문값은 각 연도 예상 실적 기준으로 산출되어 현재주가 역산값과 정확히 일치하지 않을 수 있습니다 (미래 연도 PER·PBR은 현재주가 기준으로 계산된 것으로 추정됩니다).

Sheet 15_p4_현금흐름표
A1: 추정 재무제표 — 현금흐름표
A2: 단위: 십억원 / 음영 = 전망치(F)
A4: 구분 | B4: 2023 | C4: 2024 | D4: 2025F | E4: 2026F | F4: 2027F | G4: 비고
A5: 영업활동 현금흐름 | B5: 180.7 | C5: 97.8 | D5: 182.9 | E5: 262.9 | F5: 282.1
A6: 당기순이익 | B6: 25.4 | C6: 23.8 | D6: 48.8 | E6: 149.9 | F6: 182.8
A7: 조정 | B7: 114.8 | C7: 138.3 | D7: 131.1 | E7: 94.2 | F7: 90.5
A8: 감가상각비 | B8: 115 | C8: 117.4 | D8: 101 | E8: 94.2 | F8: 90.5
A9: 외환거래손익 | B9: 1.7 | C9: -3.8 | D9: -1 | E9: 0 | F9: 0
A10: 지분법손익 | B10: 0 | C10: 0 | D10: 0 | E10: 0 | F10: 0
A11: 기타 | B11: -1.9 | C11: 24.7 | D11: 31.1 | E11: 0 | F11: 0
A12: 영업활동자산부채변동 | B12: 40.5 | C12: -64.3 | D12: 3 | E12: 18.8 | F12: 8.8
A13: 투자활동 현금흐름 | B13: -197.5 | C13: -116.1 | D13: -161.9 | E13: -155.3 | F13: -104.6
A14: 투자자산감소(증가) | B14: -1 | C14: -0.2 | D14: 0.5 | E14: -0.1 | F14: 0
A15: 자본증가(감소) | B15: -117 | C15: -59.6 | D15: -58.5 | E15: -75 | F15: -65
A16: 기타 | B16: -79.5 | C16: -56.3 | D16: -103.9 | E16: -80.2 | F16: -39.6
... A24: Free Cash Flow | B24: 63.7 | C24: 38.2 | D24: 124 | E24: 187.9 | F24: 217.1
A26: 자료: 하나증권
A28: 정합성 체크 (원문 수치를 수식으로 재계산)
A29: 체크 항목 | B29: 2023 | C29: 2024 | D29: 2025F | E29: 2026F | F29: 2027F | G29: 비고
A30: 영업+투자+재무−현금증감 (미표시 조정) | B30: =B5+B13+B17-B22 -> -0.1 | C30: =C5+C13+C17-C22 -> 0 | D30: =D5+D13+D17-D22 -> 12.9 | E30: =E5+E13+E17-E22 -> 35.8 | F30: =F5+F13+F17-F22 -> 16.8 | G30: 환율·현금성자산 분류 등 원문 미표시 조정액
A32: 주) 원문 표에는 환율효과·현금성자산 분류 조정 등 일부 조정항목이 별도 표시되지 않아 영업·투자·재무활동 합계와 현금증감 간 차이가 발생할 수 있습니다.

Sheet 16_p5_투자의견변동_괴리율
A1: 투자의견 변동 내역 및 목표주가 괴리율
A2: 하나증권 리포트 p.5 게재
A4: 날짜 | B4: 투자의견 | C4: 목표주가 | D4: 괴리율(평균) | E4: 괴리율(최고/최저) | F4: 비고
A5: 26.1.30 | B5: BUY | C5: 81000
A6: 25.11.4 | B6: BUY | C6: 59000 | D6: -0.1853 | E6: -0.0763
A7: 25.9.29 | B7: BUY | C7: 35000 | D7: -0.0302 | E7: 0.1386
A8: 25.7.29 | B8: BUY | C8: 32000 | D8: -0.236 | E8: -0.0906
A9: 25.5.21 | B9: BUY | C9: 20000 | D9: -0.139 | E9: 0.0375
A10: 25.5.13 | B10: BUY | C10: 23000 | D10: -0.3443 | E10: -0.3152
A11: 25.5.13 | B11: 담당자 변경
A12: 25.2.4 | B12: BUY | C12: 23000 | D12: -0.2739 | E12: -0.0935
A13: 24.11.1 | B13: BUY | C13: 25000 | D13: -0.3599 | E13: -0.2
A14: 24.2.7 | B14: BUY | C14: 30000 | D14: -0.2719 | E14: -0.1
A16: 자료: 하나증권
A17: 주) 괴리율 평균/최고최저는 목표주가 제시 이후 실제 주가와의 괴리율입니다. 원문 차트(대덕전자 실제주가 vs 수정TP, 24.01~26.01)는 표에 없는 월별 주가 시계열이라 옮기지 않았습니다.

Sheet 17_p5_투자등급_비율공시
A1: 투자등급 분류 기준 및 투자의견 비율공시
A2: 하나증권 리포트 p.5 게재
A4: 투자의견의 유효기간
A5: 추천일 이후 12개월을 기준으로 적용
A7: 기업의 분류
A8: BUY(매수)_목표주가가 현주가 대비 15% 이상 상승 여력
A9: Neutral(중립)_목표주가가 현주가 대비 -15%~15% 등락
A10: Reduce(비중축소)_목표주가가 현주가 대비 15% 이상 하락 가능
A12: 산업의 분류
A13: Overweight(비중확대)_업종지수가 현재지수 대비 15% 이상 상승 여력
A14: Neutral(중립)_업종지수가 현재지수 대비 -15%~15% 등락
A15: Underweight(비중축소)_업종지수가 현재지수 대비 -15%~15% 등락
A17: 투자의견 비율공시 (최근 1년)
A18: 투자등급 | B18: BUY(매수) | C18: Neutral(중립) | D18: Reduce(매도)
A19: 금융투자상품의 비율 | B19: 0.9579 | C19: 0.0421 | D19: 0 | E19: 합계 | F19: =B19+C19+D19 -> 1
A20: * 기준일: 2026년 01월 26일

Sheet D1_DART확정실적_대사
A1: DART 확정 실적 대사 — 하나증권 추정치 검증 (원문에 없는 파생 분석)
A2: DART 확정 실적과 하나증권 4Q25 리뷰 추정치 비교(연결 기준).
A4: ① 2025년 연간 실적 (사업보고서 2026.03.18, 연결)
A5: 항목 | B5: 하나증권 추정(2025F) | C5: DART 확정 | D5: 차이 | E5: 비고
A6: 매출액(십억원) | B6: ='12_p4_손익계산서'!D5 -> 1065.3 | C6: 1065.29 | D6: =C6/B6-1 -> -9.3870271e-06
A7: 영업이익(십억원) | B7: ='12_p4_손익계산서'!D9 -> 49.1 | C7: 49.06 | D7: =C7/B7-1 -> -0.00081466395
A8: 지배주주순이익(십억원) | B8: ='12_p4_손익계산서'!D19 -> 48.8 | C8: 47.61 | D8: =C8/B8-1 -> -0.024385246
A9: EPS(원, 확정 발행주식수 기준) | B9: ='14_p4_투자지표'!D6 -> 947 | C9: 924 | D9: =C9/B9-1 -> -0.024287223
A10: 자산총계(십억원) | B10: ='13_p4_대차대조표'!D17 -> 1250.6 | C10: 1178.01 | D10: =C10/B10-1 -> -0.058044139
A11: 부채총계(십억원) | B11: ='13_p4_대차대조표'!D25 -> 348.8 | C11: 280.7 | D11: =C11/B11-1 -> -0.19524083
A13: 자료: DART 대덕전자(주) 사업보고서(2026.03.18), entity01478712, 연결재무제표 (IFRS-Full: Revenue, OperatingIncomeLoss, ProfitLossAttributableToOwnersOfParent, Assets, Liabilities)
A15: ② 2026년 1분기 실적 (분기보고서 2026.05.14, 연결)
A16: 항목 | B16: 하나증권 1Q26F(수정후) | C16: DART 확정 | D16: 차이 | E16: 비고
A17: 매출액(십억원) | B17: ='10_도표6_분기실적전망_수정후'!F5 -> 330 | C17: 346.31 | D17: =C17/B17-1 -> 0.049424242 | E17: 하나증권 4Q25 리뷰(2026.01.30) 시점 이후 확정된 실적입니다
A18: 영업이익(십억원) | B18: ='10_도표6_분기실적전망_수정후'!F19 -> 40.2 | C18: 51.3 | D18: =C18/B18-1 -> 0.2761194 | E18: 하나증권 4Q25 리뷰(2026.01.30) 시점 이후 확정된 실적입니다
A19: 지배주주순이익(십억원) | B19: =M1_실적추정_모델!F26 -> 33.5 | C19: 45.5 | D19: =C19/B19-1 -> 0.35820896 | E19: 1Q26F는 4Q25 리뷰의 연간 순이익을 분기 OP 비중으로 배분한 추정값
A21: 자료: DART 대덕전자(주) 분기보고서(2026.05.14), entity01478712_2026-03-31.xbrl, 연결재무제표
A23: 주) 1Q26 확정 매출·영업이익이 하나증권의 4Q25 리뷰 시점 전망치(도표6 수정후)를 크게 상회합니다 — 반도체 기판 수요 회복이 예상보다 빨랐던 것으로 해석됩니다. 이 시트는 리뷰 작성 시점(2026.01.30) 이후 실제로 공개된 확정치와의 대사이며, M1_실적추정_모델 시트의 입력값 자체는 바꾸지 않았습니다 (리뷰 시점 가정을 지키기 위함).

Sheet Z_출처_공시_리서치
A1: 출처, 공시, 미확보 구간 정리
A3: 원문 리포트
A4: 원자료 | C4: 하나증권 「대덕전자(353200) — 기판 맹수, 앙!」 4Q25 Earnings Review, 2026.01.30, Analyst 김민경 (minkyung.kim@hanafn.com)
A6: DART 전자공시
A7: 공시서류 | B7: 접수일자 | C7: 기업 고유번호 | D7: 내용
A8: 사업보고서 (2025 사업연도) | B8: 2026.03.18 | C8: 01478712 | D8: 대덕전자(주), 연결 재무제표 IFRS 원문 XBRL. FY2023~FY2025 연간 확정 실적
A9: 분기보고서 (2026년 1분기) | B9: 2026.05.14 | C9: 01478712 | D9: 대덕전자(주), 연결 재무제표 IFRS 원문 XBRL. 1Q26 확정 실적, 1Q25 비교 표시
A11: 미확보 구간 (임의 추정하지 않음)
A12: 도표4 분기별 실적추이 (1Q21~4Q23 매출·OPM) | C12: 차트 이미지 눈금 판독 근사치로 대체 (주황 기울임 글씨). DART에 해당 기간 개별 분기 공시 없음
A13: 도표5 분기별 수주잔고 추이 (전 구간) | C13: 수주잔고는 IFRS 표준 공시 항목이 아니며 DART XBRL에 구조화 데이터로 없음. 차트 이미지 판독 근사치
A14: 03_p1_주가추이 월별 시계열 (21.1~26.1) | C14: 시세 제공 사이트 자동 수집 차단으로 미확보. 목표주가 변동 이력(16번 시트)으로 대체
A15: 도표2·3 PER/PBR Band 주가 시계열 | C15: 원문 차트에 데이터 라벨 없음. 밴드 배수만 06·07 시트에 옮김
A18: 본 파일은 하나증권 리서치 자료와 DART 전자공시를 정리한 학습·분석용 자료이며 투자 권유가 아닙니다.
A19: 추가 추정 및 시연 입력
A20: 항목 | B20: 기준 | C20: 처리 방식 | D20: 검증
A21: 분기 세전이익·지배주주순이익 | B21: 하나증권 4Q25 연간 추정치 | C21: 분기 영업이익 비중 배분, 4Q 잔여값 | D21: 분기 합계 = 연간 입력값
A22: Peer 2026E P/E | B22: 2026.01.30 리뷰 시점 | C22: 원문 미공개 개별값은 평균 26.58배를 재현하는 시연용 근사·역산값 | D22: 코리아써키트 입력 전 평균 26.58배
A23: 코리아써키트 | B23: 하나증권 1Q26 도표1 Peer 추가 | C23: 시연 입력용 빈 셀 유지 | D23: 입력 시 평균·목표주가 자동 갱신
A24: 주의 | C24: Peer 개별 P/E는 원문 직접 전사값이 아니므로 주황 기울임체로 구분
